Workbook

Sheet 00_执行总览
A1: LAMDA 云控｜一期智能体执行计划
A2: 2026-09-10 智能体执行版｜当前验收=现有 OnePlus 9R b0644fb5 单机分阶段。Note9/10台/100模拟为后期扩展（非已通过、非删除）。网页高级模型定方案，本地模型实施，达到触发条件才升级诊断。原功能与安全门禁在当前机上仍须满足，不预估人力工期。
A5: 原任务映射 | D5: 新包总数 / 仍需推进 | G5: 已记录执行轮次 | J5: 开工图最长 · 层
A6: =COUNTA('04_旧任务对照'!A6:A125)&" / 120" | D6: =COUNTA('01_闭环计划'!A6:A55)&" / "&(COUNTA('01_闭环计划'!A6:A55)-COUNTIF('01_闭环计划'!D6:D55,"沿用完成")-COUNTIF('01_闭环计划'!D6:D55,"验收通过")) | G6: =SUM('01_闭环计划'!J6:J55) | J6: =MAX('01_闭环计划'!P6:P55)
A9: 边界：50包含P00已完成成果归档，P14另已单机验收，48包仍需推进。6层=5条开工依赖边；原图20条边包含验收前置，两种口径不等于交付工期对比。新包状态不会因合并自动变完成。
A12: 当前执行模式：Root + 最多3个隔离写入子智能体；P14 WEB/CONTROL/ANDROID已合并并完成OnePlus单机版本生命周期验收。当前继续按READY规则安排P09/G3检查及P15等独立模块，设备/部署仍单队列。 2026-09-15回填：integration/p14-20260909@50b4fda。闲鱼维护三件套（擦亮/下架/删除）经受控账本GATED全部真机闭环；IM聚合（范围变更，原二期提前）真机验收通过；投屏/远控第一片集成待Q04真机；DY预提交验证过、真实发布未执行（用户指示）。09表追加5行回填，01表P09/P10/P11/P28/P29/P30按真机证据更新。权威活动计划：lamda_yun_一期计划_多智能体版.xlsx（任务状态以新表01为准）。
A13: 2026-09-10：集成分支 integration/p14-20260909，P14运行修复80a5de9/1ca0c1a，设备故障测试033e5ac/5eaa2f1。已建立独立worktree；不再重复WAIT_BASELINE。P14已解锁P15，但P15及G3尚未验收。
A14: 2026-09-15：订单同步slice1全链闭环（集成c113f0e已推送；首尔orders-7adc827；真机双方向验收6单入库；后端626/1·Android339·Web178）。现在先做：维护新路径W4增量实现（标题定位→详情→管理菜单，锚点契约已冻结，GATED删除/下架复验须用户逐件授权）→ 订单slice2（详情页订单号/断点续传） | B14: 修复companion暂停任务生命周期(服务器取消不下发→本地PAUSED行永久卡队列，Q02-B真机场景的前置)；顺带runbook化无障碍重启用设置搜索路径
A15: 2026-09-16：P09 claim断开安全释放协议完成实现+两轮对抗审阅闭环（仅CLAIMED/PREFLIGHT可释放；B1卡死/B2churn已修；Android 409、后端44测试通过）。旧UNKNOWN任务保持KEEP_WAITING严禁重试。现在先做：等待用户裁决UNKNOWN（人工核验“如果历史是一群喵4”是否仍存在）；部署/真机联调需用户逐项授权。 | B15: 修复companion暂停任务生命周期(服务器取消不下发→本地PAUSED行永久卡队列，Q02-B真机场景的前置)；顺带runbook化无障碍重启用设置搜索路径
A18: 执行实测｜累计分钟不等于日历工期 | H18: 上传快照｜原进度
A19: 执行分组 | B19: 包数 | C19: 验收通过 | D19: 执行轮次 | E19: 主动分钟* | F19: 已知成本¥* | H19: 原任务状态 | L19: 项数
A20: 继承 | B20: =COUNTIF('01_闭环计划'!B6:B55,A20) | C20: 1 | D20: 1 | E20: =IF(SUMPRODUCT(--ISNUMBER('01_闭环计划'!K6:K55),--('01_闭环计划'!B6:B55=A20))=0,"",SUMIF('01_闭环计划'!B6:B55,A20,'01_闭环计划'!K6:K55)) | F20: =IF(SUMPRODUCT(--ISNUMBER('01_闭环计划'!L6:L55),--('01_闭环计划'!B6:B55=A20))=0,"",SUMIF('01_闭环计划'!B6:B55,A20,'01_闭环计划'!L6:L55)) | H20: 已完成 | L20: =COUNTIF('04_旧任务对照'!C6:C125,H20)
A21: 主链路 | B21: =COUNTIF('01_闭环计划'!B6:B55,A21) | C21: 2 | D21: =SUMIF('01_闭环计划'!B6:B55,A21,'01_闭环计划'!J6:J55) | E21: =IF(SUMPRODUCT(--ISNUMBER('01_闭环计划'!K6:K55),--('01_闭环计划'!B6:B55=A21))=0,"",SUMIF('01_闭环计划'!B6:B55,A21,'01_闭环计划'!K6:K55)) | F21: =IF(SUMPRODUCT(--ISNUMBER('01_闭环计划'!L6:L55),--('01_闭环计划'!B6:B55=A21))=0,"",SUMIF('01_闭环计划'!B6:B55,A21,'01_闭环计划'!L6:L55)) | H21: 进行中 | L21: =COUNTIF('04_旧任务对照'!C6:C125,H21)
A22: 设备与底座 | B22: =COUNTIF('01_闭环计划'!B6:B55,A22) | C22: =COUNTIFS('01_闭环计划'!B6:B55,A22,'01_闭环计划'!D6:D55,"验收通过") | D22: =SUMIF('01_闭环计划'!B6:B55,A22,'01_闭环计划'!J6:J55) | E22: =IF(SUMPRODUCT(--ISNUMBER('01_闭环计划'!K6:K55),--('01_闭环计划'!B6:B55=A22))=0,"",SUMIF('01_闭环计划'!B6:B55,A22,'01_闭环计划'!K6:K55)) | F22: =IF(SUMPRODUCT(--ISNUMBER('01_闭环计划'!L6:L55),--('01_闭环计划'!B6:B55=A22))=0,"",SUMIF('01_闭环计划'!B6:B55,A22,'01_闭环计划'!L6:L55)) | H22: 待联调 | L22: =COUNTIF('04_旧任务对照'!C6:C125,H22)
A23: 双平台发布 | B23: =COUNTIF('01_闭环计划'!B6:B55,A23) | C23: =COUNTIFS('01_闭环计划'!B6:B55,A23,'01_闭环计划'!D6:D55,"验收通过") | D23: =SUMIF('01_闭环计划'!B6:B55,A23,'01_闭环计划'!J6:J55) | E23: =IF(SUMPRODUCT(--ISNUMBER('01_闭环计划'!K6:K55),--('01_闭环计划'!B6:B55=A23))=0,"",SUMIF('01_闭环计划'!B6:B55,A23,'01_闭环计划'!K6:K55)) | F23: =IF(SUMPRODUCT(--ISNUMBER('01_闭环计划'!L6:L55),--('01_闭环计划'!B6:B55=A23))=0,"",SUMIF('01_闭环计划'!B6:B55,A23,'01_闭环计划'!L6:L55)) | H23: 未开始 | L23: =COUNTIF('04_旧任务对照'!C6:C125,H23)
A24: 闲鱼与采集 | B24: =COUNTIF('01_闭环计划'!B6:B55,A24) | C24: =COUNTIFS('01_闭环计划'!B6:B55,A24,'01_闭环计划'!D6:D55,"验收通过") | D24: =SUMIF('01_闭环计划'!B6:B55,A24,'01_闭环计划'!J6:J55) | E24: =IF(SUMPRODUCT(--ISNUMBER('01_闭环计划'!K6:K55),--('01_闭环计划'!B6:B55=A24))=0,"",SUMIF('01_闭环计划'!B6:B55,A24,'01_闭环计划'!K6:K55)) | F24: =IF(SUMPRODUCT(--ISNUMBER('01_闭环计划'!L6:L55),--('01_闭环计划'!B6:B55=A24))=0,"",SUMIF('01_闭环计划'!B6:B55,A24,'01_闭环计划'!L6:L55)) | H24: 原审阅“代码已修/待联调” | L24: =COUNTIF('07_原审阅索引'!D6:D68,"代码已修/待联调")
A25: 交付收口 | B25: =COUNTIF('01_闭环计划'!B6:B55,A25) | C25: =COUNTIFS('01_闭环计划'!B6:B55,A25,'01_闭环计划'!D6:D55,"验收通过") | D25: =SUMIF('01_闭环计划'!B6:B55,A25,'01_闭环计划'!J6:J55) | E25: =IF(SUMPRODUCT(--ISNUMBER('01_闭环计划'!K6:K55),--('01_闭环计划'!B6:B55=A25))=0,"",SUMIF('01_闭环计划'!B6:B55,A25,'01_闭环计划'!K6:K55)) | F25: =IF(SUMPRODUCT(--ISNUMBER('01_闭环计划'!L6:L55),--('01_闭环计划'!B6:B55=A25))=0,"",SUMIF('01_闭环计划'!B6:B55,A25,'01_闭环计划'!L6:L55)) | H25: *分钟/成本为已填写项之和，缺失不当免费或零耗时；完整度见06。旧状态冲突保留，待当前代码证据核实。
A26: 合计 | B26: =SUM(B20:B25) | C26: =SUM(C20:C25) | D26: =SUM(D20:D25) | E26: =IF(COUNT(E20:E25)=0,"",SUM(E20:E25)) | F26: =IF(COUNT(F20:F25)=0,"",SUM(F20:F25))
A28: 不是删范围提速：核心通过 ≠ 一期验收通过
A29: 当前验收改为 OnePlus 9R b0644fb5 单机分阶段。原范围功能（实时视频、同任务恢复、Recipe手动发布、完整产品/帖子/资源池、双平台发布、闲鱼31目录、订单与指标历史、长期保存）在当前机上仍须满足。Note9 认证与至少10台真机（及配套100模拟容量）改为后期扩展，不得标已通过，也不得永久删除。 真实副作用前的权限、单writer、提交防重和版本安全不能后补。平台入口不存在只记阻塞。单机通过 ≠ 原多机/Note9 一期完成。
A33: 怎么用这份表
A34: 01_闭环计划 | D34: 维护D/Q状态、阻塞、下一检查点与证据；J/K/L由09执行记录自动汇总。
A35: 02_验收卡 | D35: 只读取当前P卡；主路径和必要错误验证通过即结束当前检查点。
A36: 03_启动与门禁 | D36: 启动五阶段不是五天；门禁只阻止受影响操作，独立工作继续。
A37: 04_旧任务对照 | D37: 120项旧T完整映射；保留原状态、证据、契约和验收，不重复执行旧手册。
A38: 05_范围追溯 | D38: 20需求 + 12原范围 + 31闲鱼目录；逐项验收，不静默删减。
A39: 06_执行实测 | D39: 记录轮次、主动耗时、等待与成本完整度；无实测时不推算总工期。
A40: 07索引 / 08–11执行辅助 | D40: 07只追溯；08模型/子智能体分工；09逐轮日志；10当前包交接；11多智能体并行控制台与P14工作队列。
A42: 本次修改与证据边界
A43: 基于用户提供的闭环执行版于2026-09-08调整。原50包、120项映射、需求、验收和安全门禁保留；删除原38–76人日与人数换算，不把旧估算改名为AI小时。60分钟无进展检查、同错两轮升级均为建议起始策略。调用账单未提供，费用留空。原文件保留。 2026-09-08 补记本轮执行：09表写入P08/P09/P07/P01四轮；01表Q列模块通过，D列仍非验收通过。当前仓库已检查；OnePlus 9R探针已跑通。原口径「验收通过才算整包」保留。 2026-09-08 用户已确认：当前验收改为现有 OnePlus 9R b0644fb5 单机分阶段验收。红米 Note9 认证、至少10台真机及配套100模拟容量验证推迟到单机主链路通过之后，作为后期扩展：不得标成已通过，也不得从原范围永久删除。当前机上的功能与安全门禁仍须满足；单机通过 ≠ 原多机/Note9 一期完成。权威活动计划：lamda_yun_一期计划_智能体执行版.xlsx。本轮不启动 P15、不做新真机试验。 09表追加 R20260908-06。P01/P07 去掉过期「生产claim仍发旧steps」。P14 不以 worker CLOSED 为整包通过。 2026-09-09 对照当前任务更新：P14 焦点竞争硬验收通过；新增任务 0d36fe3f… 在闲鱼前台起始时成功等待 Companion 成为活动窗口，并留下 expected/actual 日志。历史失败 7f292679 未改写，签名校验未关闭。本次复跑后端 6 项测试通过、Android Recipe 定向测试构建成功。由于该 probe 仍使用内置 Recipe，且 T041 网页入口、签名 Recipe claim 固定、暂停/运行版本固定、下载中断旧版可用、回退审计尚未闭环，P14 保持进行中/开发中。09 表追加 R20260909-01；10 表切换到版本生命周期余项。 2026-09-09 多智能体方案：新增 11_多智能体并行；采用 Root Worker + 3 子智能体。编码智能体编排位于外部开发执行层，不改造成生产 Temporal Worker。READY 由合同、写集、资源锁和验证定义决定；三个子智能体必须批量创建后统一等待。当前脏工作区先做可恢复基线冻结；子智能体使用独立 worktree/branch。P14 拆为 WEB、CONTROL、ANDROID 三路并行，Root 串行合并与真机验收。09 表追加 R20260909-02。 2026-09-15回填：按W0里程碑统一回写旧表规则，09表追加R20260913-P09-02/R20260914-SCOPE-01/R20260914-P10-01/R20260915-P29-01/R20260915-P30-01五行（明细取自新表11_执行记录；时间Asia/Shanghai；Token/费用未知留空）。01表仅改D/N/Q/R/S，J/K/L仍由公式从09汇总，未手填。

Sheet 01_闭环计划
A1: 01 / 智能体功能包执行台
A2: I列为连续主动排查无新增证据的检查阈值，不是包工期。J/L/K由09记录汇总；缺失数据不当0。Q模块自测通过可结束开发，D保留真实功能验收状态；F/G不得解释为等待前置整包完成。接口解锁见08，当前施工交接见10。
A5: 新编号 | B5: 执行分组 | C5: 功能闭环 | D5: 当前状态 | E5: 执行模型 / 责任人 | F5: 所需接口来源 MUST | G5: 接通验证相关包 非整包完成前置 | H5: 必过门禁 | I5: 无进展检查 分钟（可调） | J5: 已记录轮次 | K5: 已记录主动 分钟（可缺项） | L5: 已知调用成本 人民币（可缺项） | M5: 接口可用性 非整包状态 | N5: 证据 / 当前阻塞 | O5: 原任务归属 | P5: 开工依赖 层数 | Q5: 模块开发状态 | R5: 当前阻塞类型 | S5: 下一可见交付 / 解锁边界
A6: P00 | B6: 继承 | C6: 继承基线、审阅和架构成果 | D6: 沿用完成 | E6: 待认领 | F6: 无新增包前置 | G6: 无 | H6: G0 | I6: 0 | J6: =COUNTIFS('09_执行记录'!$B$6:$B$2022,A6,'09_执行记录'!$A$6:$A$2022,"<>") | K6: =IF(COUNTIFS('09_执行记录'!$B$6:$B$2022,A6,'09_执行记录'!$A$6:$A$2022,"<>",'09_执行记录'!$H$6:$H$2022,"<>")=0,"",SUMIFS('09_执行记录'!$H$6:$H$2022,'09_执行记录'!$B$6:$B$2022,A6,'09_执行记录'!$A$6:$A$2022,"<>")) | L6: =IF(COUNTIFS('09_执行记录'!$B$6:$B$2022,A6,'09_执行记录'!$A$6:$A$2022,"<>",'09_执行记录'!$M$6:$M$2022,"<>")=0,"",SUMIFS('09_执行记录'!$M$6:$M$2022,'09_执行记录'!$B$6:$B$2022,A6,'09_执行记录'!$A$6:$A$2022,"<>")) | M6: 可用 | N6: 沿用原表T001–T003已完成；N列未附证据链接，本次未复核，不重做全仓。 | O6: T001、T002、T003 | P6: =1 | Q6: 沿用完成 | R6: 待核实 | S6: 仅登记当前分支与已有产物位置；没有代码变化不重做T001–T003。
A7: P01 | B7: 主链路 | C7: 字段映射与双平台命令工厂 | D7: 已有实现待联调 | E7: ZCode | F7: 无新增包前置 | G7: P03；P05；P07 | H7: G1 | I7: 60 | J7: =COUNTIFS('09_执行记录'!$B$6:$B$2022,A7,'09_执行记录'!$A$6:$A$2022,"<>") | K7: =IF(COUNTIFS('09_执行记录'!$B$6:$B$2022,A7,'09_执行记录'!$A$6:$A$2022,"<>",'09_执行记录'!$H$6:$H$2022,"<>")=0,"",SUMIFS('09_执行记录'!$H$6:$H$2022,'09_执行记录'!$B$6:$B$2022,A7,'09_执行记录'!$A$6:$A$2022,"<>")) | L7: =IF(COUNTIFS('09_执行记录'!$B$6:$B$2022,A7,'09_执行记录'!$A$6:$A$2022,"<>",'09_执行记录'!$M$6:$M$2022,"<>")=0,"",SUMIFS('09_执行记录'!$M$6:$M$2022,'09_执行记录'!$B$6:$B$2022,A7,'09_执行记录'!$A$6:$A$2022,"<>")) | M7: 部分可用 | N7: 模块通过：T077工厂已接；31项目录唯一归属。生产 claim 已走 CommandV1（protocolVersion=cloudctl.command/v1）。现场 device-probe ca985a89 SUCCEEDED controlEpoch=94。OPEN_ONLY 不记发布成功。不重做 field-map。 | O7: T004、T012、T077 | P7: =1 | Q7: 模块通过 | R7: 待核实 | S7: 不重做 field-map。下一可见：与 P03/P05 联调 operationId；P14 转入版本生命周期余项。
A8: P02 | B8: 主链路 | C8: 真实登录态、API与统一权限 | D8: 模块通过 | E8: 待认领 | F8: 无新增包前置 | G8: 无 | H8: G1 | I8: 60 | J8: =COUNTIFS('09_执行记录'!$B$6:$B$2022,A8,'09_执行记录'!$A$6:$A$2022,"<>") | K8: =IF(COUNTIFS('09_执行记录'!$B$6:$B$2022,A8,'09_执行记录'!$A$6:$A$2022,"<>",'09_执行记录'!$H$6:$H$2022,"<>")=0,"",SUMIFS('09_执行记录'!$H$6:$H$2022,'09_执行记录'!$B$6:$B$2022,A8,'09_执行记录'!$A$6:$A$2022,"<>")) | L8: =IF(COUNTIFS('09_执行记录'!$B$6:$B$2022,A8,'09_执行记录'!$A$6:$A$2022,"<>",'09_执行记录'!$M$6:$M$2022,"<>")=0,"",SUMIFS('09_执行记录'!$M$6:$M$2022,'09_执行记录'!$B$6:$B$2022,A8,'09_执行记录'!$A$6:$A$2022,"<>")) | M8: 部分可用 | N8: 404/501 fail-closed + 权限单测通过；真实身份联调待补 | O8: T005、T006 | P8: =1 | Q8: 继承待核实 | R8: 待核实 | S8: 按原表已记录的/session实际实现核对路由，联调现有测试；不另造/me第二套身份。
A9: P03 | B9: 主链路 | C9: 设备及双平台账号绑定、换绑隔离 | D9: 已有实现待联调 | E9: 待认领 | F9: P01；P02 | G9: P04；P06；P08 | H9: G1/G2 | I9: 60 | J9: =COUNTIFS('09_执行记录'!$B$6:$B$2022,A9,'09_执行记录'!$A$6:$A$2022,"<>") | K9: =IF(COUNTIFS('09_执行记录'!$B$6:$B$2022,A9,'09_执行记录'!$A$6:$A$2022,"<>",'09_执行记录'!$H$6:$H$2022,"<>")=0,"",SUMIFS('09_执行记录'!$H$6:$H$2022,'09_执行记录'!$B$6:$B$2022,A9,'09_执行记录'!$A$6:$A$2022,"<>")) | L9: =IF(COUNTIFS('09_执行记录'!$B$6:$B$2022,A9,'09_执行记录'!$A$6:$A$2022,"<>",'09_执行记录'!$M$6:$M$2022,"<>")=0,"",SUMIFS('09_执行记录'!$M$6:$M$2022,'09_执行记录'!$B$6:$B$2022,A9,'09_执行记录'!$A$6:$A$2022,"<>")) | M9: 部分可用 | N9: 002/003 SQL + ACCOUNT_CHANGED逻辑已有；迁移未上生产 | O9: T007、T010、T011、T086 | P9: =MAX(P7,P8)+1 | Q9: 继承待核实 | R9: 待核实 | S9: 复用002/003迁移与现有绑定接口，先在可回滚环境应用并验证；核对T011把暂停计划记为CANCELED的语义。
A10: P04 | B10: 主链路 | C10: 设备、平台能力探测与兼容底稿 | D10: 已有实现待联调 | E10: 待认领 | F10: 无新增包前置 | G10: P03；P07 | H10: G1/G7 | I10: 60 | J10: =COUNTIFS('09_执行记录'!$B$6:$B$2022,A10,'09_执行记录'!$A$6:$A$2022,"<>") | K10: =IF(COUNTIFS('09_执行记录'!$B$6:$B$2022,A10,'09_执行记录'!$A$6:$A$2022,"<>",'09_执行记录'!$H$6:$H$2022,"<>")=0,"",SUMIFS('09_执行记录'!$H$6:$H$2022,'09_执行记录'!$B$6:$B$2022,A10,'09_执行记录'!$A$6:$A$2022,"<>")) | L10: =IF(COUNTIFS('09_执行记录'!$B$6:$B$2022,A10,'09_执行记录'!$A$6:$A$2022,"<>",'09_执行记录'!$M$6:$M$2022,"<>")=0,"",SUMIFS('09_执行记录'!$M$6:$M$2022,'09_执行记录'!$B$6:$B$2022,A10,'09_执行记录'!$A$6:$A$2022,"<>")) | M10: 部分可用 | N10: heartbeat扩展字段已有。当前验收机为 OnePlus 9R b0644fb5，单机证据保留。Note9 认证与10台容量改为后期扩展，不作为当前阻塞，也不得标已通过。 | O10: T008、T009 | P10: =1 | Q10: 继承待核实 | R10: 待核实 | S10: 复用现有 OnePlus 9R 报告做当前机能力探测。Note9/多机认证推迟，不在本阶段把其资源缺口当当前阻塞。
A11: P05 | B11: 主链路 | C11: 统一任务事实、事件与任务工作台 | D11: 已有实现待联调 | E11: 待认领 | F11: P01；P02 | G11: P06；P08；P12 | H11: G1/G2 | I11: 60 | J11: =COUNTIFS('09_执行记录'!$B$6:$B$2022,A11,'09_执行记录'!$A$6:$A$2022,"<>") | K11: =IF(COUNTIFS('09_执行记录'!$B$6:$B$2022,A11,'09_执行记录'!$A$6:$A$2022,"<>",'09_执行记录'!$H$6:$H$2022,"<>")=0,"",SUMIFS('09_执行记录'!$H$6:$H$2022,'09_执行记录'!$B$6:$B$2022,A11,'09_执行记录'!$A$6:$A$2022,"<>")) | L11: =IF(COUNTIFS('09_执行记录'!$B$6:$B$2022,A11,'09_执行记录'!$A$6:$A$2022,"<>",'09_执行记录'!$M$6:$M$2022,"<>")=0,"",SUMIFS('09_执行记录'!$M$6:$M$2022,'09_执行记录'!$B$6:$B$2022,A11,'09_执行记录'!$A$6:$A$2022,"<>")) | M11: 部分可用 | N11: platform_tasks.py + 004 SQL已有；迁移未上生产 | O11: T013、T014、T028 | P11: =MAX(P7,P8)+1 | Q11: 继承待核实 | R11: 待核实 | S11: 应用并验证004迁移；沿用现有API和事件schema，先让一个真实taskId在网页完整可见。
A12: P06 | B12: 主链路 | C12: 快照冻结与立即、预约、周期调度 | D12: 已有实现待联调 | E12: 待认领 | F12: P01；P05 | G12: P03；P17；P19；P20 | H12: G1/G3 | I12: 60 | J12: =COUNTIFS('09_执行记录'!$B$6:$B$2022,A12,'09_执行记录'!$A$6:$A$2022,"<>") | K12: =IF(COUNTIFS('09_执行记录'!$B$6:$B$2022,A12,'09_执行记录'!$A$6:$A$2022,"<>",'09_执行记录'!$H$6:$H$2022,"<>")=0,"",SUMIFS('09_执行记录'!$H$6:$H$2022,'09_执行记录'!$B$6:$B$2022,A12,'09_执行记录'!$A$6:$A$2022,"<>")) | L12: =IF(COUNTIFS('09_执行记录'!$B$6:$B$2022,A12,'09_执行记录'!$A$6:$A$2022,"<>",'09_执行记录'!$M$6:$M$2022,"<>")=0,"",SUMIFS('09_执行记录'!$M$6:$M$2022,'09_执行记录'!$B$6:$B$2022,A12,'09_执行记录'!$A$6:$A$2022,"<>")) | M12: 部分可用 | N12: schedules.py + ScheduleEditor + 006 SQL已有；Temporal未接线 | O12: T015、T017、T018 | P12: =MAX(P7,P11)+1 | Q12: 继承待核实 | R12: 待核实 | S12: 先补T017的Temporal接线与006迁移，再验证一次定时触发；资源解析按P19/P20接口联调。
A13: P07 | B13: 主链路 | C13: 本地Recipe生产接线与执行生命周期 | D13: 已有实现待联调 | E13: ZCode | F13: P01；P04 | G13: P03；P05；P08；P14；P17 | H13: G1/G2/G4 | I13: 60 | J13: =COUNTIFS('09_执行记录'!$B$6:$B$2022,A13,'09_执行记录'!$A$6:$A$2022,"<>") | K13: =IF(COUNTIFS('09_执行记录'!$B$6:$B$2022,A13,'09_执行记录'!$A$6:$A$2022,"<>",'09_执行记录'!$H$6:$H$2022,"<>")=0,"",SUMIFS('09_执行记录'!$H$6:$H$2022,'09_执行记录'!$B$6:$B$2022,A13,'09_执行记录'!$A$6:$A$2022,"<>")) | L13: =IF(COUNTIFS('09_执行记录'!$B$6:$B$2022,A13,'09_执行记录'!$A$6:$A$2022,"<>",'09_执行记录'!$M$6:$M$2022,"<>")=0,"",SUMIFS('09_执行记录'!$M$6:$M$2022,'09_执行记录'!$B$6:$B$2022,A13,'09_执行记录'!$A$6:$A$2022,"<>")) | M13: 部分可用 | N13: 模块通过：生产 claim 已走 CommandV1 并接 RecipeEngine；无 legacy steps。OnePlus 探针 67d95d4a SUCCEEDED controlEpoch=93。内置 Recipe 不是 P14 已发布目录。OPEN_ONLY 不记发布成功。 | O13: T019、T020、T021、T022 | P13: =MAX(P7,P10)+1 | Q13: 模块通过 | R13: 待核实 | S13: P14 焦点硬验收已于 2026-09-09 通过；P07 不重开 CommandV1/焦点诊断。继续由 P14 验证已发布签名 Recipe 的版本固定、回退与审计。
A14: P08 | B14: 主链路 | C14: 单写锁与暂停→人工→同task恢复 | D14: 核心通过 | E14: ZCode | F14: 现有T026/T023/T016接口可先用 | G14: P03；P05；P07；P09 | H14: G2；真实副作用另须G3 | I14: 60 | J14: =COUNTIFS('09_执行记录'!$B$6:$B$2022,A14,'09_执行记录'!$A$6:$A$2022,"<>") | K14: =IF(COUNTIFS('09_执行记录'!$B$6:$B$2022,A14,'09_执行记录'!$A$6:$A$2022,"<>",'09_执行记录'!$H$6:$H$2022,"<>")=0,"",SUMIFS('09_执行记录'!$H$6:$H$2022,'09_执行记录'!$B$6:$B$2022,A14,'09_执行记录'!$A$6:$A$2022,"<>")) | L14: =IF(COUNTIFS('09_执行记录'!$B$6:$B$2022,A14,'09_执行记录'!$A$6:$A$2022,"<>",'09_执行记录'!$M$6:$M$2022,"<>")=0,"",SUMIFS('09_执行记录'!$M$6:$M$2022,'09_执行记录'!$B$6:$B$2022,A14,'09_执行记录'!$A$6:$A$2022,"<>")) | M14: 部分可用 | N14: 2026-09-10：caa22da3 CommandV1签名任务，PAUSED_WAITING_USER后保留数据安装APK，原taskId恢复RUNNING，resumeCount=2，保持1.0.3并从hold继续，started未重放；pageVerified=false拒绝409。取证后主动取消。其他G2故障不据此自动通过。见 cloudctl-source/artifacts/tasks/P14-multi-agent/P14-INTEGRATION-ACCEPTANCE/summary.md | O14: T016、T023、T026、T027 | P14: =1 | Q14: 模块通过 | R14: 待核实 | S14: 同taskId续跑不再重复开发；后续补失租立停等G2故障，P09/G3真实副作用门禁仍未过。
A15: P09 | B15: 主链路 | C15: 共享提交门禁与不确定结果核对 | D15: 进行中 | E15: ZCode | F15: P01；P08 | G15: P03；P14；P26；P28；P30；P32；P37 | H15: G3（不可后置） | I15: 60 | J15: =COUNTIFS('09_执行记录'!$B$6:$B$2022,A15,'09_执行记录'!$A$6:$A$2022,"<>") | K15: =IF(COUNTIFS('09_执行记录'!$B$6:$B$2022,A15,'09_执行记录'!$A$6:$A$2022,"<>",'09_执行记录'!$H$6:$H$2022,"<>")=0,"",SUMIFS('09_执行记录'!$H$6:$H$2022,'09_执行记录'!$B$6:$B$2022,A15,'09_执行记录'!$A$6:$A$2022,"<>")) | L15: =IF(COUNTIFS('09_执行记录'!$B$6:$B$2022,A15,'09_执行记录'!$A$6:$A$2022,"<>",'09_执行记录'!$M$6:$M$2022,"<>")=0,"",SUMIFS('09_执行记录'!$M$6:$M$2022,'09_执行记录'!$B$6:$B$2022,A15,'09_执行记录'!$A$6:$A$2022,"<>")) | M15: 部分可用 | N15: 2026-09-16：claim断开安全释放协议已实现并通过两轮对抗审阅：仅CLAIMED/PREFLIGHT可释放，首次heartbeat为执行边界，GATED/RECONCILING全阻断；B1卡死与B2 churn已修复确认。Android 409/后端44测试通过；未部署未连设备；旧UNKNOWN未触碰。 | O15: T024、T025 | P15: =MAX(P7,P14)+1 | Q15: 模块通过 | R15: 等待用户对UNKNOWN任务a25549e5的裁决（继续KEEP_WAITING或人工核验商品状态）；工程侧后续为部署release端点到首尔并构建安装新APK做真机联调，均需用户明确授权 | S15: cloudctl-source/artifacts/tasks/P09-unknown/xianyu-maintenance-20260916/release-protocol-evidence.md
A16: P10 | B16: 设备与底座 | C16: WebRTC会话、采集与实时播放器 | D16: 进行中 | E16: 待认领 | F16: P02；P04 | G16: P48 | H16: G1/G5 | I16: 60 | J16: =COUNTIFS('09_执行记录'!$B$6:$B$2022,A16,'09_执行记录'!$A$6:$A$2022,"<>") | K16: =IF(COUNTIFS('09_执行记录'!$B$6:$B$2022,A16,'09_执行记录'!$A$6:$A$2022,"<>",'09_执行记录'!$H$6:$H$2022,"<>")=0,"",SUMIFS('09_执行记录'!$H$6:$H$2022,'09_执行记录'!$B$6:$B$2022,A16,'09_执行记录'!$A$6:$A$2022,"<>")) | L16: =IF(COUNTIFS('09_执行记录'!$B$6:$B$2022,A16,'09_执行记录'!$A$6:$A$2022,"<>",'09_执行记录'!$M$6:$M$2022,"<>")=0,"",SUMIFS('09_执行记录'!$M$6:$M$2022,'09_执行记录'!$B$6:$B$2022,A16,'09_执行记录'!$A$6:$A$2022,"<>")) | M16: 未核实 | N16: 2026-09-14回填：投屏/远控第一片（JPEG帧流，WebRTC后置）已集成02a10fd：后端51过1跳；Android 197/0；web typecheck+build过。契约p10-live/20260913.1冻结。真机SIM观看/远控验收（Q04）待Root持锁。 | O16: T029、T030、T031、T032 | P16: =MAX(P8,P10)+1 | Q16: 模块通过 | R16: 待真机验收 | S16: 先做单机Q04真机验收（观看→远控交还）；WebRTC升级与长时观看重连（P12）后置；最小成功≠整包验收。
A17: P11 | B17: 设备与底座 | C17: 远控面板、手势输入与交还自动化 | D17: 进行中 | E17: 待认领 | F17: P08；P10；P07 | G17: P03；P12 | H17: G2/G5 | I17: 60 | J17: =COUNTIFS('09_执行记录'!$B$6:$B$2022,A17,'09_执行记录'!$A$6:$A$2022,"<>") | K17: =IF(COUNTIFS('09_执行记录'!$B$6:$B$2022,A17,'09_执行记录'!$A$6:$A$2022,"<>",'09_执行记录'!$H$6:$H$2022,"<>")=0,"",SUMIFS('09_执行记录'!$H$6:$H$2022,'09_执行记录'!$B$6:$B$2022,A17,'09_执行记录'!$A$6:$A$2022,"<>")) | L17: =IF(COUNTIFS('09_执行记录'!$B$6:$B$2022,A17,'09_执行记录'!$A$6:$A$2022,"<>",'09_执行记录'!$M$6:$M$2022,"<>")=0,"",SUMIFS('09_执行记录'!$M$6:$M$2022,'09_执行记录'!$B$6:$B$2022,A17,'09_执行记录'!$A$6:$A$2022,"<>")) | M17: 未核实 | N17: 2026-09-14回填：远控动作交接随实时会话第一片交付（集成02a10fd，Android 197/0）；输入通道经IM聚合自有IME闭环（焦点门禁/快照契约/会话抖动三层修复，终验6步SUCCEEDED）。完整接管→点击→交还路径待Q04真机。 | O17: T034、T035、T036、T037 | P17: =MAX(P14,P16,P13)+1 | Q17: 模块通过（第一片） | R17: 待真机验收 | S17: Q04真机验收接管→点击→交还完整路径；手势输入边界后补。
A18: P12 | B18: 设备与底座 | C18: 长时观看、重连与设备工作台 | D18: 未开始 | E18: 待认领 | F18: P10；P05 | G18: P04；P11 | H18: G5 | I18: 60 | J18: =COUNTIFS('09_执行记录'!$B$6:$B$2022,A18,'09_执行记录'!$A$6:$A$2022,"<>") | K18: =IF(COUNTIFS('09_执行记录'!$B$6:$B$2022,A18,'09_执行记录'!$A$6:$A$2022,"<>",'09_执行记录'!$H$6:$H$2022,"<>")=0,"",SUMIFS('09_执行记录'!$H$6:$H$2022,'09_执行记录'!$B$6:$B$2022,A18,'09_执行记录'!$A$6:$A$2022,"<>")) | L18: =IF(COUNTIFS('09_执行记录'!$B$6:$B$2022,A18,'09_执行记录'!$A$6:$A$2022,"<>",'09_执行记录'!$M$6:$M$2022,"<>")=0,"",SUMIFS('09_执行记录'!$M$6:$M$2022,'09_执行记录'!$B$6:$B$2022,A18,'09_执行记录'!$A$6:$A$2022,"<>")) | M18: 未核实 | N18: 原任务未开始；状态继承原上传快照；当前仓库与运行结果待核实。 | O18: T033、T038 | P18: =MAX(P16,P11)+1 | Q18: 继承待核实 | R18: 待核实 | S18: 让同一个DeviceLiveScreen进入设备详情；复用P10首帧证据，集中做30分钟与网络切换。
A19: P13 | B19: 设备与底座 | C19: 页面定位器采样与版本回归 | D19: 未开始 | E19: 待认领 | F19: P04；P07 | G19: P08；P14 | H19: G2/G4 | I19: 60 | J19: =COUNTIFS('09_执行记录'!$B$6:$B$2022,A19,'09_执行记录'!$A$6:$A$2022,"<>") | K19: =IF(COUNTIFS('09_执行记录'!$B$6:$B$2022,A19,'09_执行记录'!$A$6:$A$2022,"<>",'09_执行记录'!$H$6:$H$2022,"<>")=0,"",SUMIFS('09_执行记录'!$H$6:$H$2022,'09_执行记录'!$B$6:$B$2022,A19,'09_执行记录'!$A$6:$A$2022,"<>")) | L19: =IF(COUNTIFS('09_执行记录'!$B$6:$B$2022,A19,'09_执行记录'!$A$6:$A$2022,"<>",'09_执行记录'!$M$6:$M$2022,"<>")=0,"",SUMIFS('09_执行记录'!$M$6:$M$2022,'09_执行记录'!$B$6:$B$2022,A19,'09_执行记录'!$A$6:$A$2022,"<>")) | M19: 未核实 | N19: 原任务未开始；状态继承原上传快照；当前仓库与运行结果待核实。 | O19: T039 | P19: =MAX(P10,P13)+1 | Q19: 继承待核实 | R19: 待核实 | S19: 先采登录/首页/发布/列表等首条闭环所需页面；后续页面随相应业务包补齐。
A20: P14 | B20: 设备与底座 | C20: Recipe手动发布、签名校验与回退 | D20: 验收通过 | E20: Root Worker + 子智能体×3 | F20: P01；P02 | G20: P07；P08；P13 | H20: G4 | I20: 60 | J20: =COUNTIFS('09_执行记录'!$B$6:$B$2022,A20,'09_执行记录'!$A$6:$A$2022,"<>") | K20: =IF(COUNTIFS('09_执行记录'!$B$6:$B$2022,A20,'09_执行记录'!$A$6:$A$2022,"<>",'09_执行记录'!$H$6:$H$2022,"<>")=0,"",SUMIFS('09_执行记录'!$H$6:$H$2022,'09_执行记录'!$B$6:$B$2022,A20,'09_执行记录'!$A$6:$A$2022,"<>")) | L20: =IF(COUNTIFS('09_执行记录'!$B$6:$B$2022,A20,'09_执行记录'!$A$6:$A$2022,"<>",'09_执行记录'!$M$6:$M$2022,"<>")=0,"",SUMIFS('09_执行记录'!$M$6:$M$2022,'09_执行记录'!$B$6:$B$2022,A20,'09_执行记录'!$A$6:$A$2022,"<>")) | M20: 可用 | N20: 2026-09-10 OnePlus单机验收通过：网页人工登记/发布/回退；签名版本真实领取执行；caa22da3同任务运行中发布新版、暂停、APK重启、恢复均固定1.0.3且不重放已完成步；真实HTTPS 685→32字节截断时保留1.0.1，恢复后自动验签激活1.0.4；最后回退1.0.1并由c8ec815c探针成功。62 Android单测、3真机存储故障测试通过。见 cloudctl-source/artifacts/tasks/P14-multi-agent/P14-INTEGRATION-ACCEPTANCE/summary.md | O20: T040、T041、T042 | P20: =MAX(P7,P8)+1 | Q20: 模块通过 | R20: 无 | S20: P14依赖已解锁；允许按READY规则安排P15。P08同任务恢复已补证，其他G2故障及P09/G3仍需独立验收。公网Basic Auth登录未计入本次通过范围。
A21: P15 | B21: 设备与底座 | C21: APK整包升级与系统确认 | D21: 未开始 | E21: 待认领 | F21: P04；P14 | G21: P08；P09 | H21: G2/G4 | I21: 60 | J21: =COUNTIFS('09_执行记录'!$B$6:$B$2022,A21,'09_执行记录'!$A$6:$A$2022,"<>") | K21: =IF(COUNTIFS('09_执行记录'!$B$6:$B$2022,A21,'09_执行记录'!$A$6:$A$2022,"<>",'09_执行记录'!$H$6:$H$2022,"<>")=0,"",SUMIFS('09_执行记录'!$H$6:$H$2022,'09_执行记录'!$B$6:$B$2022,A21,'09_执行记录'!$A$6:$A$2022,"<>")) | L21: =IF(COUNTIFS('09_执行记录'!$B$6:$B$2022,A21,'09_执行记录'!$A$6:$A$2022,"<>",'09_执行记录'!$M$6:$M$2022,"<>")=0,"",SUMIFS('09_执行记录'!$M$6:$M$2022,'09_执行记录'!$B$6:$B$2022,A21,'09_执行记录'!$A$6:$A$2022,"<>")) | M21: 未核实 | N21: 原任务未开始；状态继承原上传快照；当前仓库与运行结果待核实。 | O21: T043 | P21: =MAX(P10,P20)+1 | Q21: 继承待核实 | R21: 待核实 | S21: 在现有Companion上做一次保留数据升级；不引入Root/Device Owner或静默安装前提。
A22: P16 | B22: 设备与底座 | C22: 媒体上传、持久资产与权限 | D22: 未开始 | E22: 待认领 | F22: P02 | G22: 无 | H22: G1/G6 | I22: 60 | J22: =COUNTIFS('09_执行记录'!$B$6:$B$2022,A22,'09_执行记录'!$A$6:$A$2022,"<>") | K22: =IF(COUNTIFS('09_执行记录'!$B$6:$B$2022,A22,'09_执行记录'!$A$6:$A$2022,"<>",'09_执行记录'!$H$6:$H$2022,"<>")=0,"",SUMIFS('09_执行记录'!$H$6:$H$2022,'09_执行记录'!$B$6:$B$2022,A22,'09_执行记录'!$A$6:$A$2022,"<>")) | L22: =IF(COUNTIFS('09_执行记录'!$B$6:$B$2022,A22,'09_执行记录'!$A$6:$A$2022,"<>",'09_执行记录'!$M$6:$M$2022,"<>")=0,"",SUMIFS('09_执行记录'!$M$6:$M$2022,'09_执行记录'!$B$6:$B$2022,A22,'09_执行记录'!$A$6:$A$2022,"<>")) | M22: 未核实 | N22: 原任务未开始，本次未重跑代码。 审阅B007/B015标已修，但关联任务仍未开始；先核实复用改动。 | O22: T044、T045 | P22: =MAX(P8)+1 | Q22: 继承待核实 | R22: 待核实 | S22: 先把MediaAsset接口/fixture提供给编辑器和下载模块；后端与上传UI同一包完成。
A23: P17 | B23: 设备与底座 | C23: 素材下发、流式下载与确定选取 | D23: 未开始 | E23: 待认领 | F23: P16；P06；P07 | G23: P03；P13；P14 | H23: G1/G2/G3 | I23: 60 | J23: =COUNTIFS('09_执行记录'!$B$6:$B$2022,A23,'09_执行记录'!$A$6:$A$2022,"<>") | K23: =IF(COUNTIFS('09_执行记录'!$B$6:$B$2022,A23,'09_执行记录'!$A$6:$A$2022,"<>",'09_执行记录'!$H$6:$H$2022,"<>")=0,"",SUMIFS('09_执行记录'!$H$6:$H$2022,'09_执行记录'!$B$6:$B$2022,A23,'09_执行记录'!$A$6:$A$2022,"<>")) | L23: =IF(COUNTIFS('09_执行记录'!$B$6:$B$2022,A23,'09_执行记录'!$A$6:$A$2022,"<>",'09_执行记录'!$M$6:$M$2022,"<>")=0,"",SUMIFS('09_执行记录'!$M$6:$M$2022,'09_执行记录'!$B$6:$B$2022,A23,'09_执行记录'!$A$6:$A$2022,"<>")) | M23: 未核实 | N23: 原任务未开始，本次未重跑代码。 审阅B025标已修，但关联任务仍未开始；先核实复用改动。 | O23: T046、T047、T048 | P23: =MAX(P22,P12,P13)+1 | Q23: 继承待核实 | R23: 待核实 | S23: 先下发一图一视频验证manifest；再在真实图库验证选取，不等完整发布页面全部完成。
A24: P18 | B24: 设备与底座 | C24: 文件推送与截图证据闭环 | D24: 未开始 | E24: 待认领 | F24: P16；P17 | G24: P05；P11 | H24: G1/G6 | I24: 60 | J24: =COUNTIFS('09_执行记录'!$B$6:$B$2022,A24,'09_执行记录'!$A$6:$A$2022,"<>") | K24: =IF(COUNTIFS('09_执行记录'!$B$6:$B$2022,A24,'09_执行记录'!$A$6:$A$2022,"<>",'09_执行记录'!$H$6:$H$2022,"<>")=0,"",SUMIFS('09_执行记录'!$H$6:$H$2022,'09_执行记录'!$B$6:$B$2022,A24,'09_执行记录'!$A$6:$A$2022,"<>")) | L24: =IF(COUNTIFS('09_执行记录'!$B$6:$B$2022,A24,'09_执行记录'!$A$6:$A$2022,"<>",'09_执行记录'!$M$6:$M$2022,"<>")=0,"",SUMIFS('09_执行记录'!$M$6:$M$2022,'09_执行记录'!$B$6:$B$2022,A24,'09_执行记录'!$A$6:$A$2022,"<>")) | M24: 未核实 | N24: 原任务未开始，本次未重跑代码。 审阅B028标已修，但关联任务仍未开始；先核实复用改动。 | O24: T049、T050 | P24: =MAX(P22,P23)+1 | Q24: 继承待核实 | R24: 待核实 | S24: 复用MediaDelivery与资产上传，不新建独立文件服务；先做一次推送和一次失败截图。
A25: P19 | B25: 设备与底座 | C25: 水印配置、派生素材与真实预览 | D25: 未开始 | E25: 待认领 | F25: P16 | G25: P06；P21；P28 | H25: G3/G6 | I25: 60 | J25: =COUNTIFS('09_执行记录'!$B$6:$B$2022,A25,'09_执行记录'!$A$6:$A$2022,"<>") | K25: =IF(COUNTIFS('09_执行记录'!$B$6:$B$2022,A25,'09_执行记录'!$A$6:$A$2022,"<>",'09_执行记录'!$H$6:$H$2022,"<>")=0,"",SUMIFS('09_执行记录'!$H$6:$H$2022,'09_执行记录'!$B$6:$B$2022,A25,'09_执行记录'!$A$6:$A$2022,"<>")) | L25: =IF(COUNTIFS('09_执行记录'!$B$6:$B$2022,A25,'09_执行记录'!$A$6:$A$2022,"<>",'09_执行记录'!$M$6:$M$2022,"<>")=0,"",SUMIFS('09_执行记录'!$M$6:$M$2022,'09_执行记录'!$B$6:$B$2022,A25,'09_执行记录'!$A$6:$A$2022,"<>")) | M25: 未核实 | N25: 原任务未开始；状态继承原上传快照；当前仓库与运行结果待核实。 | O25: T051、T052、T053 | P25: =MAX(P22)+1 | Q25: 继承待核实 | R25: 待核实 | S25: 复用现有派生工作流；一个模板贯通配置→预览→输出asset，随后补全field-map有效字段。
A26: P20 | B26: 设备与底座 | C26: 地址、描述和标签共享资源池 | D26: 未开始 | E26: 待认领 | F26: P02；P03 | G26: P06；P21；P28 | H26: G1/G3 | I26: 60 | J26: =COUNTIFS('09_执行记录'!$B$6:$B$2022,A26,'09_执行记录'!$A$6:$A$2022,"<>") | K26: =IF(COUNTIFS('09_执行记录'!$B$6:$B$2022,A26,'09_执行记录'!$A$6:$A$2022,"<>",'09_执行记录'!$H$6:$H$2022,"<>")=0,"",SUMIFS('09_执行记录'!$H$6:$H$2022,'09_执行记录'!$B$6:$B$2022,A26,'09_执行记录'!$A$6:$A$2022,"<>")) | L26: =IF(COUNTIFS('09_执行记录'!$B$6:$B$2022,A26,'09_执行记录'!$A$6:$A$2022,"<>",'09_执行记录'!$M$6:$M$2022,"<>")=0,"",SUMIFS('09_执行记录'!$M$6:$M$2022,'09_执行记录'!$B$6:$B$2022,A26,'09_执行记录'!$A$6:$A$2022,"<>")) | M26: 未核实 | N26: 原任务未开始；状态继承原上传快照；当前仓库与运行结果待核实。 | O26: T054、T055、T056、T057 | P26: =MAX(P8,P9)+1 | Q26: 继承待核实 | R26: 待核实 | S26: 先交共享PoolSelectionSnapshot与CRUD，再接三个薄页面；不为每类池重复建库存储。
A27: P21 | B27: 设备与底座 | C27: 商品模型、编辑、分组与列表 | D27: 未开始 | E27: 待认领 | F27: P02；P16 | G27: P19；P20 | H27: G1/G6 | I27: 60 | J27: =COUNTIFS('09_执行记录'!$B$6:$B$2022,A27,'09_执行记录'!$A$6:$A$2022,"<>") | K27: =IF(COUNTIFS('09_执行记录'!$B$6:$B$2022,A27,'09_执行记录'!$A$6:$A$2022,"<>",'09_执行记录'!$H$6:$H$2022,"<>")=0,"",SUMIFS('09_执行记录'!$H$6:$H$2022,'09_执行记录'!$B$6:$B$2022,A27,'09_执行记录'!$A$6:$A$2022,"<>")) | L27: =IF(COUNTIFS('09_执行记录'!$B$6:$B$2022,A27,'09_执行记录'!$A$6:$A$2022,"<>",'09_执行记录'!$M$6:$M$2022,"<>")=0,"",SUMIFS('09_执行记录'!$M$6:$M$2022,'09_执行记录'!$B$6:$B$2022,A27,'09_执行记录'!$A$6:$A$2022,"<>")) | M27: 未核实 | N27: 原任务T058–T062未开始；但B001标代码已修/待联调，先核实可复用变更，勿重复修复。 审阅B001/B007/B005/B006标已修，但关联任务仍未开始；先核实复用改动。 | O27: T058、T059、T060、T061、T062 | P27: =MAX(P8,P22)+1 | Q27: 继承待核实 | R27: 待核实 | S27: 先做价格/外键迁移与一条商品编辑闭环，再接列表分组；水印/池字段允许先接契约，但整包验收不能漏联调。
A28: P22 | B28: 设备与底座 | C28: 商品导入与安全导出 | D28: 未开始 | E28: 待认领 | F28: P21；P16 | G28: P24；P41 | H28: G1/G6 | I28: 60 | J28: =COUNTIFS('09_执行记录'!$B$6:$B$2022,A28,'09_执行记录'!$A$6:$A$2022,"<>") | K28: =IF(COUNTIFS('09_执行记录'!$B$6:$B$2022,A28,'09_执行记录'!$A$6:$A$2022,"<>",'09_执行记录'!$H$6:$H$2022,"<>")=0,"",SUMIFS('09_执行记录'!$H$6:$H$2022,'09_执行记录'!$B$6:$B$2022,A28,'09_执行记录'!$A$6:$A$2022,"<>")) | L28: =IF(COUNTIFS('09_执行记录'!$B$6:$B$2022,A28,'09_执行记录'!$A$6:$A$2022,"<>",'09_执行记录'!$M$6:$M$2022,"<>")=0,"",SUMIFS('09_执行记录'!$M$6:$M$2022,'09_执行记录'!$B$6:$B$2022,A28,'09_执行记录'!$A$6:$A$2022,"<>")) | M28: 未核实 | N28: 原任务未开始；状态继承原上传快照；当前仓库与运行结果待核实。 | O28: T063、T064、T065、T070 | P28: =MAX(P27,P22)+1 | Q28: 继承待核实 | R28: 待核实 | S28: 固定小样本：正常、错误行、重复批次、缺媒体；先跑后端批次，再接预览/提交页面。
A29: P23 | B29: 设备与底座 | C29: 一次性旧浏览器数据迁移 | D29: 未开始 | E29: 待认领 | F29: P21；P20；P19 | G29: P24 | H29: G6 | I29: 60 | J29: =COUNTIFS('09_执行记录'!$B$6:$B$2022,A29,'09_执行记录'!$A$6:$A$2022,"<>") | K29: =IF(COUNTIFS('09_执行记录'!$B$6:$B$2022,A29,'09_执行记录'!$A$6:$A$2022,"<>",'09_执行记录'!$H$6:$H$2022,"<>")=0,"",SUMIFS('09_执行记录'!$H$6:$H$2022,'09_执行记录'!$B$6:$B$2022,A29,'09_执行记录'!$A$6:$A$2022,"<>")) | L29: =IF(COUNTIFS('09_执行记录'!$B$6:$B$2022,A29,'09_执行记录'!$A$6:$A$2022,"<>",'09_执行记录'!$M$6:$M$2022,"<>")=0,"",SUMIFS('09_执行记录'!$M$6:$M$2022,'09_执行记录'!$B$6:$B$2022,A29,'09_执行记录'!$A$6:$A$2022,"<>")) | M29: 未核实 | N29: 原任务未开始；状态继承原上传快照；当前仓库与运行结果待核实。 | O29: T066 | P29: =MAX(P27,P26,P25)+1 | Q29: 继承待核实 | R29: 待核实 | S29: 先备份一份旧localStorage样本；与P22复用预检能力，只迁移真实数据。
A30: P24 | B30: 设备与底座 | C30: 帖子编辑、分组、修订与归档 | D30: 未开始 | E30: 待认领 | F30: P02；P16 | G30: 无 | H30: G1/G6 | I30: 60 | J30: =COUNTIFS('09_执行记录'!$B$6:$B$2022,A30,'09_执行记录'!$A$6:$A$2022,"<>") | K30: =IF(COUNTIFS('09_执行记录'!$B$6:$B$2022,A30,'09_执行记录'!$A$6:$A$2022,"<>",'09_执行记录'!$H$6:$H$2022,"<>")=0,"",SUMIFS('09_执行记录'!$H$6:$H$2022,'09_执行记录'!$B$6:$B$2022,A30,'09_执行记录'!$A$6:$A$2022,"<>")) | L30: =IF(COUNTIFS('09_执行记录'!$B$6:$B$2022,A30,'09_执行记录'!$A$6:$A$2022,"<>",'09_执行记录'!$M$6:$M$2022,"<>")=0,"",SUMIFS('09_执行记录'!$M$6:$M$2022,'09_执行记录'!$B$6:$B$2022,A30,'09_执行记录'!$A$6:$A$2022,"<>")) | M30: 未核实 | N30: 原任务未开始，本次未重跑代码。 审阅B012/B015标已修，但关联任务仍未开始；先核实复用改动。 | O30: T067、T068、T069 | P30: =MAX(P8,P22)+1 | Q30: 继承待核实 | R30: 待核实 | S30: 先做一篇图文与一篇视频内容的跨浏览器保存，再接列表/分组，不混入手机发布。
A31: P25 | B31: 双平台发布 | C31: 小红书发布命令与统一页面入口 | D31: 未开始 | E31: 待认领 | F31: P01；P06；P24 | G31: P03；P12；P26；P27 | H31: G1/G3/G4 | I31: 60 | J31: =COUNTIFS('09_执行记录'!$B$6:$B$2022,A31,'09_执行记录'!$A$6:$A$2022,"<>") | K31: =IF(COUNTIFS('09_执行记录'!$B$6:$B$2022,A31,'09_执行记录'!$A$6:$A$2022,"<>",'09_执行记录'!$H$6:$H$2022,"<>")=0,"",SUMIFS('09_执行记录'!$H$6:$H$2022,'09_执行记录'!$B$6:$B$2022,A31,'09_执行记录'!$A$6:$A$2022,"<>")) | L31: =IF(COUNTIFS('09_执行记录'!$B$6:$B$2022,A31,'09_执行记录'!$A$6:$A$2022,"<>",'09_执行记录'!$M$6:$M$2022,"<>")=0,"",SUMIFS('09_执行记录'!$M$6:$M$2022,'09_执行记录'!$B$6:$B$2022,A31,'09_执行记录'!$A$6:$A$2022,"<>")) | M31: 未核实 | N31: 原任务未开始；状态继承原上传快照；当前仓库与运行结果待核实。 | O31: T071、T076 | P31: =MAX(P7,P12,P30)+1 | Q31: 继承待核实 | R31: 待核实 | S31: 先修小红书生产允许列表并从网页生成真实命令；Recipe可先用同契约fixture开发，但不能据此记发布成功。
A32: P26 | B32: 双平台发布 | C32: 小红书图文发布与草稿完整流程 | D32: 未开始 | E32: 待认领 | F32: P07；P13；P17 | G32: P03；P09；P14；P18；P25；P27 | H32: G2/G3/G4 | I32: 60 | J32: =COUNTIFS('09_执行记录'!$B$6:$B$2022,A32,'09_执行记录'!$A$6:$A$2022,"<>") | K32: =IF(COUNTIFS('09_执行记录'!$B$6:$B$2022,A32,'09_执行记录'!$A$6:$A$2022,"<>",'09_执行记录'!$H$6:$H$2022,"<>")=0,"",SUMIFS('09_执行记录'!$H$6:$H$2022,'09_执行记录'!$B$6:$B$2022,A32,'09_执行记录'!$A$6:$A$2022,"<>")) | L32: =IF(COUNTIFS('09_执行记录'!$B$6:$B$2022,A32,'09_执行记录'!$A$6:$A$2022,"<>",'09_执行记录'!$M$6:$M$2022,"<>")=0,"",SUMIFS('09_执行记录'!$M$6:$M$2022,'09_执行记录'!$B$6:$B$2022,A32,'09_执行记录'!$A$6:$A$2022,"<>")) | M32: 未核实 | N32: 原任务未开始；状态继承原上传快照；当前仓库与运行结果待核实。 | O32: T072、T073、T075 | P32: =MAX(P13,P19,P23)+1 | Q32: 继承待核实 | R32: 待核实 | S32: 先做已发布Recipe的图文主路径，再同批验证草稿与一次提交后断网；不等待视频全完才调图文。
A33: P27 | B33: 双平台发布 | C33: 小红书视频笔记、封面与处理等待 | D33: 未开始 | E33: 待认领 | F33: P26；P17 | G33: P09；P14；P25 | H33: G2/G3/G4 | I33: 60 | J33: =COUNTIFS('09_执行记录'!$B$6:$B$2022,A33,'09_执行记录'!$A$6:$A$2022,"<>") | K33: =IF(COUNTIFS('09_执行记录'!$B$6:$B$2022,A33,'09_执行记录'!$A$6:$A$2022,"<>",'09_执行记录'!$H$6:$H$2022,"<>")=0,"",SUMIFS('09_执行记录'!$H$6:$H$2022,'09_执行记录'!$B$6:$B$2022,A33,'09_执行记录'!$A$6:$A$2022,"<>")) | L33: =IF(COUNTIFS('09_执行记录'!$B$6:$B$2022,A33,'09_执行记录'!$A$6:$A$2022,"<>",'09_执行记录'!$M$6:$M$2022,"<>")=0,"",SUMIFS('09_执行记录'!$M$6:$M$2022,'09_执行记录'!$B$6:$B$2022,A33,'09_执行记录'!$A$6:$A$2022,"<>")) | M33: 未核实 | N33: 原任务未开始；状态继承原上传快照；当前仓库与运行结果待核实。 | O33: T074 | P33: =MAX(P32,P23)+1 | Q33: 继承待核实 | R33: 待核实 | S33: 直接在P26共用Recipe能力上增加VIDEO分支；不要重复建设任务工厂、账号校验或结果上报。
A34: P28 | B34: 双平台发布 | C34: 闲鱼商品发布完整闭环 | D34: 验收通过 | E34: 待认领 | F34: P21；P07；P17 | G34: P01；P03；P06；P09；P12；P13；P14；P18；P19；P20 | H34: G2/G3/G4 | I34: 60 | J34: =COUNTIFS('09_执行记录'!$B$6:$B$2022,A34,'09_执行记录'!$A$6:$A$2022,"<>") | K34: =IF(COUNTIFS('09_执行记录'!$B$6:$B$2022,A34,'09_执行记录'!$A$6:$A$2022,"<>",'09_执行记录'!$H$6:$H$2022,"<>")=0,"",SUMIFS('09_执行记录'!$H$6:$H$2022,'09_执行记录'!$B$6:$B$2022,A34,'09_执行记录'!$A$6:$A$2022,"<>")) | L34: =IF(COUNTIFS('09_执行记录'!$B$6:$B$2022,A34,'09_执行记录'!$A$6:$A$2022,"<>",'09_执行记录'!$M$6:$M$2022,"<>")=0,"",SUMIFS('09_执行记录'!$M$6:$M$2022,'09_执行记录'!$B$6:$B$2022,A34,'09_执行记录'!$A$6:$A$2022,"<>")) | M34: 未核实 | N34: Q03真机验收通过2026-09-16：任务24c923bb(v1.1.1图全12态绿→WAITING_USER确认点)→人工填价9.90+发布→在卖187(+1)「云控平台验收测试服务¥9.9」；证据 artifacts/parallel/W5/Q03/run7-24c923bb/；遗留：PAUSED任务卡队列(问题清单) | O34: T078、T079、T080、T081 | P34: =MAX(P27,P13,P23)+1 | Q34: 模块通过 | R34: 无 | S34: 补齐完整字段+水印+资源池后整包验收；批量发布随维护定位方案解。
A35: P29 | B35: 闲鱼与采集 | C35: 擦亮、上下架与快速下架 | D35: 进行中 | E35: 待认领 | F35: P01；P07；P13 | G35: P03；P08；P09；P14 | H35: G2/G3/G4 | I35: 60 | J35: =COUNTIFS('09_执行记录'!$B$6:$B$2022,A35,'09_执行记录'!$A$6:$A$2022,"<>") | K35: =IF(COUNTIFS('09_执行记录'!$B$6:$B$2022,A35,'09_执行记录'!$A$6:$A$2022,"<>",'09_执行记录'!$H$6:$H$2022,"<>")=0,"",SUMIFS('09_执行记录'!$H$6:$H$2022,'09_执行记录'!$B$6:$B$2022,A35,'09_执行记录'!$A$6:$A$2022,"<>")) | L35: =IF(COUNTIFS('09_执行记录'!$B$6:$B$2022,A35,'09_执行记录'!$A$6:$A$2022,"<>",'09_执行记录'!$M$6:$M$2022,"<>")=0,"",SUMIFS('09_执行记录'!$M$6:$M$2022,'09_执行记录'!$B$6:$B$2022,A35,'09_执行记录'!$A$6:$A$2022,"<>")) | M35: 未核实 | N35: v2标题定位新路径已实现并装机；无意图干跑：导航→标题卡片→详情→管理菜单全通，确认弹窗GATED拦截止零副作用(在卖187不变)；真实下架复验待用户授权 | O35: T082、T083、T084、T101 | P35: =MAX(P7,P13,P19)+1 | Q35: 模块通过 | R35: 批量动作待定位方案 | S35: 批量下架随删除稳健定位方案解；titleContains待做；一轮设备会话覆盖多动作复用待验。
A36: P30 | B36: 闲鱼与采集 | C36: 商品、动态与留言安全删除 | D36: 进行中 | E36: 待认领 | F36: P01；P07；P13 | G36: P03；P08；P09；P14 | H36: G2/G3/G4 | I36: 60 | J36: =COUNTIFS('09_执行记录'!$B$6:$B$2022,A36,'09_执行记录'!$A$6:$A$2022,"<>") | K36: =IF(COUNTIFS('09_执行记录'!$B$6:$B$2022,A36,'09_执行记录'!$A$6:$A$2022,"<>",'09_执行记录'!$H$6:$H$2022,"<>")=0,"",SUMIFS('09_执行记录'!$H$6:$H$2022,'09_执行记录'!$B$6:$B$2022,A36,'09_执行记录'!$A$6:$A$2022,"<>")) | L36: =IF(COUNTIFS('09_执行记录'!$B$6:$B$2022,A36,'09_执行记录'!$A$6:$A$2022,"<>",'09_执行记录'!$M$6:$M$2022,"<>")=0,"",SUMIFS('09_执行记录'!$M$6:$M$2022,'09_执行记录'!$B$6:$B$2022,A36,'09_执行记录'!$A$6:$A$2022,"<>")) | M36: 未核实 | N36: v2删除路径同批就绪(已下架tab标题定位)；BADGE_UNREADABLE集成缝已修复(v2降级UNKNOWN→操作员核验)；真实删除复验待用户逐件授权 | O36: T085、T094、T096 | P36: =MAX(P7,P13,P19)+1 | Q36: 模块通过 | R36: 稳健定位未选型 | S36: 长期稳健定位三选一（详情页管理入口936,2245已勘察/tabs相对偏移/platformItemId映射）后再放开批量；留言/动态删除未开始。
A37: P31 | B37: 闲鱼与采集 | C37: 签到与鱼币抵扣设置 | D37: 未开始 | E37: 待认领 | F37: P01；P07；P13 | G37: P03；P09；P14 | H37: G2/G3/G4 | I37: 60 | J37: =COUNTIFS('09_执行记录'!$B$6:$B$2022,A37,'09_执行记录'!$A$6:$A$2022,"<>") | K37: =IF(COUNTIFS('09_执行记录'!$B$6:$B$2022,A37,'09_执行记录'!$A$6:$A$2022,"<>",'09_执行记录'!$H$6:$H$2022,"<>")=0,"",SUMIFS('09_执行记录'!$H$6:$H$2022,'09_执行记录'!$B$6:$B$2022,A37,'09_执行记录'!$A$6:$A$2022,"<>")) | L37: =IF(COUNTIFS('09_执行记录'!$B$6:$B$2022,A37,'09_执行记录'!$A$6:$A$2022,"<>",'09_执行记录'!$M$6:$M$2022,"<>")=0,"",SUMIFS('09_执行记录'!$M$6:$M$2022,'09_执行记录'!$B$6:$B$2022,A37,'09_执行记录'!$A$6:$A$2022,"<>")) | M37: 未核实 | N37: 原任务未开始；状态继承原上传快照；当前仓库与运行结果待核实。 | O37: T087、T088 | P37: =MAX(P7,P13,P19)+1 | Q37: 继承待核实 | R37: 待核实 | S37: 先验证当日签到读回，再验证抵扣设置及只打开模式；不把不同操作合成同一成功计数。
A38: P32 | B38: 闲鱼与采集 | C38: 鱼币推广与预算防重 | D38: 未开始 | E38: 待认领 | F38: P01；P07；P13 | G38: P03；P09；P14 | H38: G3必须先过 | I38: 60 | J38: =COUNTIFS('09_执行记录'!$B$6:$B$2022,A38,'09_执行记录'!$A$6:$A$2022,"<>") | K38: =IF(COUNTIFS('09_执行记录'!$B$6:$B$2022,A38,'09_执行记录'!$A$6:$A$2022,"<>",'09_执行记录'!$H$6:$H$2022,"<>")=0,"",SUMIFS('09_执行记录'!$H$6:$H$2022,'09_执行记录'!$B$6:$B$2022,A38,'09_执行记录'!$A$6:$A$2022,"<>")) | L38: =IF(COUNTIFS('09_执行记录'!$B$6:$B$2022,A38,'09_执行记录'!$A$6:$A$2022,"<>",'09_执行记录'!$M$6:$M$2022,"<>")=0,"",SUMIFS('09_执行记录'!$M$6:$M$2022,'09_执行记录'!$B$6:$B$2022,A38,'09_执行记录'!$A$6:$A$2022,"<>")) | M38: 未核实 | N38: 原任务未开始；状态继承原上传快照；当前仓库与运行结果待核实。 | O38: T089 | P38: =MAX(P7,P13,P19)+1 | Q38: 继承待核实 | R38: 待核实 | S38: 先验证无提交的预算/套餐检查与变更拒绝，再对明确授权的最小目标执行一次真实推广。
A39: P33 | B39: 闲鱼与采集 | C39: 小刀设置与价格下调 | D39: 未开始 | E39: 待认领 | F39: P01；P07；P13 | G39: P03；P09；P14；P21 | H39: G2/G3/G4 | I39: 60 | J39: =COUNTIFS('09_执行记录'!$B$6:$B$2022,A39,'09_执行记录'!$A$6:$A$2022,"<>") | K39: =IF(COUNTIFS('09_执行记录'!$B$6:$B$2022,A39,'09_执行记录'!$A$6:$A$2022,"<>",'09_执行记录'!$H$6:$H$2022,"<>")=0,"",SUMIFS('09_执行记录'!$H$6:$H$2022,'09_执行记录'!$B$6:$B$2022,A39,'09_执行记录'!$A$6:$A$2022,"<>")) | L39: =IF(COUNTIFS('09_执行记录'!$B$6:$B$2022,A39,'09_执行记录'!$A$6:$A$2022,"<>",'09_执行记录'!$M$6:$M$2022,"<>")=0,"",SUMIFS('09_执行记录'!$M$6:$M$2022,'09_执行记录'!$B$6:$B$2022,A39,'09_执行记录'!$A$6:$A$2022,"<>")) | M39: 未核实 | N39: 原任务未开始；状态继承原上传快照；当前仓库与运行结果待核实。 | O39: T090、T091 | P39: =MAX(P7,P13,P19)+1 | Q39: 继承待核实 | R39: 待核实 | S39: 先按原field-map核对枚举，分别做一个设置与一个明确降价目标；不把小刀当百分比降价。
A40: P34 | B40: 闲鱼与采集 | C40: 真实订单好评任务 | D40: 未开始 | E40: 待认领 | F40: P01；P07；P13 | G40: P03；P09；P14 | H40: G2/G3/G4 | I40: 60 | J40: =COUNTIFS('09_执行记录'!$B$6:$B$2022,A40,'09_执行记录'!$A$6:$A$2022,"<>") | K40: =IF(COUNTIFS('09_执行记录'!$B$6:$B$2022,A40,'09_执行记录'!$A$6:$A$2022,"<>",'09_执行记录'!$H$6:$H$2022,"<>")=0,"",SUMIFS('09_执行记录'!$H$6:$H$2022,'09_执行记录'!$B$6:$B$2022,A40,'09_执行记录'!$A$6:$A$2022,"<>")) | L40: =IF(COUNTIFS('09_执行记录'!$B$6:$B$2022,A40,'09_执行记录'!$A$6:$A$2022,"<>",'09_执行记录'!$M$6:$M$2022,"<>")=0,"",SUMIFS('09_执行记录'!$M$6:$M$2022,'09_执行记录'!$B$6:$B$2022,A40,'09_执行记录'!$A$6:$A$2022,"<>")) | M40: 未核实 | N40: 原任务未开始；状态继承原上传快照；当前仓库与运行结果待核实。 | O40: T092 | P40: =MAX(P7,P13,P19)+1 | Q40: 继承待核实 | R40: 待核实 | S40: 准备明确授权且可评价的真实订单；先核验目标范围，再单次评价取证。
A41: P35 | B41: 闲鱼与采集 | C41: 标准权限内重启闲鱼 | D41: 未开始 | E41: 待认领 | F41: P04；P07 | G41: P01；P03 | H41: G2 | I41: 60 | J41: =COUNTIFS('09_执行记录'!$B$6:$B$2022,A41,'09_执行记录'!$A$6:$A$2022,"<>") | K41: =IF(COUNTIFS('09_执行记录'!$B$6:$B$2022,A41,'09_执行记录'!$A$6:$A$2022,"<>",'09_执行记录'!$H$6:$H$2022,"<>")=0,"",SUMIFS('09_执行记录'!$H$6:$H$2022,'09_执行记录'!$B$6:$B$2022,A41,'09_执行记录'!$A$6:$A$2022,"<>")) | L41: =IF(COUNTIFS('09_执行记录'!$B$6:$B$2022,A41,'09_执行记录'!$A$6:$A$2022,"<>",'09_执行记录'!$M$6:$M$2022,"<>")=0,"",SUMIFS('09_执行记录'!$M$6:$M$2022,'09_执行记录'!$B$6:$B$2022,A41,'09_执行记录'!$A$6:$A$2022,"<>")) | M41: 未核实 | N41: 原任务未开始；状态继承原上传快照；当前仓库与运行结果待核实。 | O41: T093 | P41: =MAX(P10,P13)+1 | Q41: 继承待核实 | R41: 待核实 | S41: 复用已有launchTargetApp兜底，只补任务kind和结果语义；不要重写启动服务。
A42: P36 | B42: 闲鱼与采集 | C42: 消息删除与小红点处理 | D42: 未开始 | E42: 待认领 | F42: P01；P07；P13 | G42: P03；P09；P14 | H42: 删除分支须G3 | I42: 60 | J42: =COUNTIFS('09_执行记录'!$B$6:$B$2022,A42,'09_执行记录'!$A$6:$A$2022,"<>") | K42: =IF(COUNTIFS('09_执行记录'!$B$6:$B$2022,A42,'09_执行记录'!$A$6:$A$2022,"<>",'09_执行记录'!$H$6:$H$2022,"<>")=0,"",SUMIFS('09_执行记录'!$H$6:$H$2022,'09_执行记录'!$B$6:$B$2022,A42,'09_执行记录'!$A$6:$A$2022,"<>")) | L42: =IF(COUNTIFS('09_执行记录'!$B$6:$B$2022,A42,'09_执行记录'!$A$6:$A$2022,"<>",'09_执行记录'!$M$6:$M$2022,"<>")=0,"",SUMIFS('09_执行记录'!$M$6:$M$2022,'09_执行记录'!$B$6:$B$2022,A42,'09_执行记录'!$A$6:$A$2022,"<>")) | M42: 未核实 | N42: 原任务未开始；状态继承原上传快照；当前仓库与运行结果待核实。 | O42: T095 | P42: =MAX(P7,P13,P19)+1 | Q42: 继承待核实 | R42: 待核实 | S42: 先做只读/点红点分支，再用授权测试对话验证删除；不把两分支都映射为delete。
...

Sheet 02_验收卡
A1: 02 / 单包验收卡
A2: 每次只读取当前一个P包。模块自测达到固定契约可记01表Q列模块通过；整包真实场景通过才更新D列验收。代码路径是旧计划线索，施工前定向核实。按包内检查点执行，不按天等待或重复开启完整流程。
A5: 新编号 | B5: 功能包 | C5: 接手后的第一步 | D5: 核心通过标准 | E5: 整包验收 / 停止条件 | F5: 验证批次 | G5: 原代码定位线索 | H5: 旧任务 / 原表行
A6: P00 | B6: 继承基线、审阅和架构成果 | C6: 仅登记当前分支与已有产物位置；没有代码变化不重做T001–T003。 | D6: 继承原表已完成状态，不重跑全仓审阅，不再生成一轮8步骤任务。 | E6: 保留原SHA与现有ADR；N列缺失的提交/日志链接在交接时补齐。沿用完成不代表本次复核通过。 | F6: 无需重复真机 | G6: README.md；AGENTS.md；package.json；pyproject.toml；mobile/companion；apps/{web,studio}；services/*；edge/gateway；mobile/{companion,dpc}；packages/*；infra；tests；docs/adr（新增一期ADR）；services/control-api；services/temporal-worker；packages/automation-sdk | H6: T001；T002；T003｜原02表行6,7,8
A7: P01 | B7: 字段映射与双平台命令工厂 | C7: T077工厂已接。下一步与P03/P05联调operationId，不重做field-map。 | D7: 31项目录与所有启用字段有唯一归属；Python/TS/Kotlin使用同一CommandV1 fixture；工厂能生成分型参数，不依赖具体Recipe已实现。 | E7: 实际claim使用同版CommandV1；小红书允许列表贯通；未知字段/错设备拒绝；OPEN_ONLY不记执行成功。目录最终逐项验收归P49。 | F7: 契约测试为主 | G7: apps/web/src/data/operations-catalog.ts；views/OperationView.vue或实际动态页面分发入口（全库定位）；contracts/phase1（新增）；packages/api-contracts；services/control-api/src/cloudctl_api/mobile_schemas.py；APK parser；apps/web/src/views/XianyuSimpleTaskView.vue；XianyuExtraTaskView.vue；后端XianyuCommandFactory | H7: T004；T012；T077｜原02表行9,17,82
A8: P02 | B8: 真实登录态、API与统一权限 | C8: 按原表已记录的/session实际实现核对路由，联调现有测试；不另造/me第二套身份。 | D8: 复用已有session/API模式与权限集合；生产404/501失败即停止，不回退localStorage。 | E8: 真实登录读写通过；跨tenant/设备拒绝；低权限不能远控/发版；401/409/500不触发后续副作用。 | F8: API/浏览器，无强制真机 | G8: apps/web/src/api/product-catalog.ts；api/post-catalog.ts；stores/session.ts；env.d.ts；services/control-api/src/cloudctl_api/auth.py；services.py；mobile_routes.py；packages/domain权限定义 | H8: T005；T006｜原02表行10,11
A9: P03 | B9: 设备及双平台账号绑定、换绑隔离 | C9: 复用002/003迁移与现有绑定接口，先在可回滚环境应用并验证；核对T011把暂停计划记为CANCELED的语义。 | D9: 同设备每平台仅一个BOUND；闲鱼与小红书可并存；注册/重绑撤销旧凭据并递增版本。 | E9: SIM注册心跳；旧token拒绝；换绑旧任务ACCOUNT_CHANGED且历史归原账号；周期计划按约定暂停；绑定入口不保存平台密码。 | F9: 同批验证注册、双平台、换绑 | G9: services/control-api/src/cloudctl_api/mobile_service.py、db.py；mobile/companion/app/src/main/java/com/company/cloudctl/companion/security/与network/；services/control-api/src/cloudctl_api/services.py bind_account_device；mobile_service.py account_status；db.py；发布/订单/统计模型；账号页面；任务创建服务；apps/web/src/views/XianyuSimpleTaskView.vue或XianyuExtraTaskView.vue（按operation映射）；新增版本化Recipe xianyu.bind_account | H9: T007；T010；T011；T086｜原02表行12,15,16,91
A10: P04 | B10: 设备、平台能力探测与兼容底稿 | C10: 复用现有 OnePlus 9R 报告做当前机探测。Note9/10台改为后期扩展，不作为当前阻塞，也不得填通过。 | D10: 自动上报SDK/ROM、两平台包版本及权限能力，不要求用户填版本；缺能力明确reason。 | E10: 权限撤销及WiFi/SIM切换在当前机可见；卸载/未知包拒绝。Note9实际报告推迟；OnePlus 证据不能替代 Note9 认证。 | F10: 当前机开发与单机验收；Note9/多机认证为后期扩展，另见P49 | G10: mobile/companion/app/src/main/java/com/company/cloudctl/companion/device/LocalHealthCollector；service/CompanionSyncService.kt；services/control-api/src/cloudctl_api/mobile_schemas.py；mobile/companion/app/src/main/java/com/company/cloudctl/companion/automation/TargetLocatorRegistry.kt；services/control-api/src/cloudctl_api/mobile_service.py、db.py | H10: T008；T009｜原02表行13,14
A11: P05 | B11: 统一任务事实、事件与任务工作台 | C11: 应用并验证004迁移；沿用现有API和事件schema，先让一个真实taskId在网页完整可见。 | D11: 唯一PlatformTask/MobileTask事实、游标历史、幂等创建和结构化事件；队列/详情读取真实API。 | E11: 双击仅一任务；同设备FIFO、跨设备并行；暂停/失败/取消区分；刷新保留历史；恢复入口最终连接P08而非假按钮。 | F11: 与P07/P08共用一批任务证据 | G11: services/control-api/src/cloudctl_api/db.py、services.py、mobile_service.py；新增platform_tasks.py/routes；contracts/phase1/events/results；services/control-api/src/cloudctl_api/mobile_schemas.py、mobile_service.py；apps/web/src/views/TaskQueue/TaskDetail（按现有路由复用）；新增共用任务组件 | H11: T013；T014；T028｜原02表行18,19,33
A12: P06 | B12: 快照冻结与立即、预约、周期调度 | C12: 先补T017的Temporal接线与006迁移，再验证一次定时触发；资源解析按P19/P20接口联调。 | D12: 复用现有快照及ScheduleEditor；接通真实Temporal触发，不把API手动触发视为预约已完成。 | E12: 预约自动触发、周期幂等、停用不再触发；多设备独立taskId；时区/补发策略明确；资源选值/文案/素材在快照冻结，重试不漂移。 | F12: 预约与发布共用证据，调度边界自动化 | G12: 复用PublishSnapshotRow；新增通用TaskSnapshot或等价结构；services/control-api/src/cloudctl_api/services.py；services/temporal-worker；services/outbox-dispatcher；新增schedule模型/API；apps/web/src/components/ScheduleEditor.vue（新增）；所有一期任务表单 | H12: T015；T017；T018｜原02表行20,22,23
A13: P07 | B13: 本地Recipe生产接线与执行生命周期 | C13: CommandV1生产领取已接。下一步P14：人工签名发布候选Recipe到测试机。 | D13: 现有RecipeEngine接上真实领取链路；云端下发高层命令，手机本地执行，旧steps只保留兼容入口。 | E13: 真机下载并执行获准发布的指定Recipe；续租/事件上传不被主循环阻塞；未知页暂停；取消、下载失败和权限缺失不假成功。 | F13: 同包最多两批：真实领取/异常 | G13: contracts/phase1/recipe-manifest.schema.json（新增）；packages/automation-sdk；mobile/companion/app/src/main/java/com/company/cloudctl/companion/automation/（新增RecipeEngine/RecipeRegistry/RecipeContext）；mobile/companion/app/src/main/java/com/company/cloudctl/companion/service/CompanionSyncService.kt；automation/CloudCtlAccessibilityService.kt；mobile/companion/app/src/main/java/com/company/cloudctl/companion/data/AutomationStore.kt；service/CompanionSyncService.kt；network/ | H13: T019；T020；T021；T022｜原02表行24,25,26,27
A14: P08 | B14: 单写锁与暂停→人工→同task恢复 | C14: 暂停/取消/恢复门禁已接。下一步用探针补CommandV1同task续跑；不含最终提交。 | D14: 直接从T026现有成功现场接T027：暂停确认→人工处理→RESUME_CHECK→同taskId续跑，队头阻塞保持。 | E14: 继续原检查点而非第1步；旧epoch/未核对页面不得执行；失租立停；取消不可恢复；已有提交不重放；账号/版本不一致维持暂停。 | F14: 复用T026证据；补1批恢复与主要拒绝分支 | G14: services/control-api/src/cloudctl_api/mobile_service.py claim；services.py acquire_lease；db.py DeviceLeaseRow；APK执行门禁；mobile/companion/app/src/main/java/com/company/cloudctl/companion/data/AutomationStore.kt；automation/RecipeContext；PlatformTask状态机；APK RecipeContext cancel/pause token；控制API；POST task:resume；APK ResumeValidator；任务详情按钮 | H14: T016；T023；T026；T027｜原02表行21,28,31,32
A15: P09 | B15: 共享提交门禁与不确定结果核对 | C15: 双端RECONCILING加固已部署，89后端/78Android/3设备计数测试通过。真实提交接线与G3仍待验，见 cloudctl-source/artifacts/tasks/P09-unknown/hardening-20260910.md | D15: 复用ActionJournal：INTENT/APPLIED/UNKNOWN；同actionKey已成功不再执行；无可靠核对结果则保持暂停/RECONCILING。 | E15: 发布/扣费/删除前确认且参数冻结；点击后断网、丢ACK不盲重试；核对有证据才收敛；预算变化重新确认；不承诺第三方UI严格exactly-once。 | F15: 共享故障场景集中一批；各动作保留独立结果 | G15: 复用发布commit ledger；APK新增ActionJournal；服务端操作结果账；新增ReconciliationService；平台Recipe核对分支；Web任务详情 | H15: T024；T025｜原02表行29,30
A16: P10 | B16: WebRTC会话、采集与实时播放器 | C16: 包内依次交付：会话/授权→首帧→SIM relay；每段实际通过即可推进，不为每段另建任务单或重复审阅。 | D16: 打通手机授权采集→WebRTC信令/TURN→网页真实视频；只读观看不占设备写锁。 | E16: SIM公网强制relay可用；拒绝投屏授权明确显示；切换设备不串屏；断网不假实时；无观看者不持续高码率上传。720p/约20fps仅原稿建议起点。 | F16: 首帧与公网两批；记录实际耗时，30分钟稳定性观察要求另按G5保留。 | G16: control-api新增RealtimeSessionService；复用edge-hub连接职责；部署TURN；mobile/companion/app/src/main/java/com/company/cloudctl/companion/新增screen/ScreenCaptureService.kt；AndroidManifest.xml；授权Activity；mobile/companion/app/src/main/java/com/company/cloudctl/companion/新增realtime/PeerSessionManager.kt；apps/web/src/views/DeviceDetailView.vue；新增components/DeviceLiveScreen.vue | H16: T029；T030；T031；T032｜原02表行34,35,36,37
... A55: P49 | B55: Note9认证、31目录与一期交接 | C55: 当前只维护 OnePlus 9R 单机分阶段证据；Note9/10台推迟。最后跨模块交接不重跑120套手册。 | D55: 从启动起维护需求/目录证据；仅复用相关代码、契约和环境未变化的已通过用例。 | E55: 单机阶段不要求 Note9/10台通过。原 R01–R20、31目录、原120任务归属仍保留；平台不可用项保持阻塞。Note9/10台不得标已通过或永久删除，须在后期扩展中验收。 | F55: 当前 OnePlus 不得冒充 Note9；后期扩展验收不默认豁免 | G55: apps/web/src/data/operations-catalog.ts；导航/状态标签；帮助内容；docs/phase1/device-certification.md；版本包fixtures和真机证据索引；docs/phase1/acceptance.md；本Excel进度/证据列；release manifest | H55: T104；T117；T120｜原02表行109,122,125

Sheet 03_启动与门禁
A1: 03 / 从今天开始怎么推进
A2: S1–S5是启动阶段，不是天数或智能体轮数。以检查点证据推进；受阻操作停止并保留原卡，独立工作可继续。无进展检查与同错升级见08，不虚构总工期。
A5: 类型 | B5: 时段 / 编号 | C5: 目标 / 规则 | D5: 具体动作 / 准入 | E5: 不能做 / 停止条件 | F5: 交付证据 | G5: 责任 / 资源 | H5: 口径
A6: 启动阶段 | B6: S1 | C6: 先补恢复，不重新拆暂停 | D6: P08：复用T026现场完成不含最终提交的暂停→人工→同task续跑；P09：检查UNKNOWN停止与已有账本。 | E6: 不重复做T001–T003；不在门禁未过时点击真实发布/扣费/删除。 | F6: 同taskId、检查点、pauseAck、队头不越过、拒绝旧epoch的记录。 | G6: 主执行者；现有开发机 | H6: 先交无最终提交的恢复证据，不要求本阶段整包通过
A7: 启动阶段 | B7: S2 | C7: 真实身份与绑定迁移 | D7: P02 + P03前半：核实已有session/权限；在可回滚环境验证002/003等当前缺失迁移和旧token撤销。 | E7: 不直接未经备份上生产；不把单测通过当已迁移。 | F7: 真实API响应、迁移版本、旧凭据拒绝记录。 | G7: 主执行者；可回滚数据库 | H7: 实际通过即推进；缺接口/环境明确记录
A8: 启动阶段 | B8: S3 | C8: 收口契约与可用资源 | D8: P03剩余 + P01核心 + P04探测：修允许列表/工厂映射；核对当前 OnePlus 9R、目标账号可用性。Note9/10台推迟为后期扩展。 | E8: 不等定位器全集才写任务工厂；不把 OnePlus 当 Note9；推迟≠已通过。 | F8: 三端同fixture；资源缺口清单；真实版本报告。 | G8: 主执行者；用户/设备管理者配合 | H8: 资源探测启动即可做，不另增开发任务
A9: 启动阶段 | B9: S4 | C9: 让真实任务能被观察 | D9: P04剩余 + P05核心：核实004迁移，贯通创建、查询、事件、暂停/取消状态。 | E9: 不新增第二套队列/状态源；不靠前端缓存伪造成功。 | F9: 网页与服务端同一个taskId、结构化结果、刷新历史。 | G9: 主执行者 | H9: 先交真实任务可见证据，完整UI随后接通
A10: 启动阶段 | B10: S5 | C10: 打通生产领取入口，不绕发布门禁 | D10: P07接线与主链路联调；P06记录Temporal最小触发接线点。若缺合法已发布Recipe，先插入P14最小人工发布交付。 | E10: 不关闭签名、不伪造发布或真机成功；阶段不是交付时限。 | F10: CommandV1真实领取/拒绝记录；缺少发布包时明确阻塞及下一步。 | G10: 主执行者 | H10: 按实际缺口继续，不追加一轮8步骤
A11: 门禁 | B11: G0 | C11: 存量继承 | D11: T001–T003沿用，T026已有证据复用；核实分支和缺失证据即可。 | E11: 沿用完成≠本次重新验收；合包不得把部分完成自动变全完成。 | F11: 原T/新P映射；commit/证据路径补齐。 | G11: 功能包负责人+验收人 | H11: 原计划约束保留；本版集中管理
A12: 门禁 | B12: G1 | C12: 真实API与权限 | D12: 真实身份、tenant/设备隔离、401/409/500失败停止；API缺失明确失败。 | E12: 禁止生产静默localStorage/mock回退；不能用UI权限代替后端鉴权。 | F12: 真实API及负向测试；旧凭据/越权均拒绝。 | G12: 功能包负责人+验收人 | H12: 原计划约束保留；本版集中管理
A13: 门禁 | B13: G2 | C13: 设备单writer与安全恢复 | D13: 任何真实自动化/远控先验证单写锁、失租停止、暂停握手、检查点与绑定/版本核对。 | E13: 禁止AUTO与REMOTE并发写；禁止未核对页面就续跑；取消不可恢复。 | F13: Postgres并发、旧epoch拒绝、同task恢复与队头阻塞。 | G13: 功能包负责人+验收人 | H13: 原计划约束保留；本版集中管理
A14: 门禁 | B14: G3 | C14: 不可逆副作用准入 | D14: 发布/扣费/删除先确认目标与参数、写journal；UNKNOWN保持暂停/核对；成功项不重做。 | E14: 不可作为日后补测试的可选项；不得无证据重发或超预算。 | F14: 每类动作主路径+提交后断网/丢ACK；预算/目标变化拒绝。 | G14: 功能包负责人+验收人 | H14: 原计划约束保留；本版集中管理
A15: 门禁 | B15: G4 | C15: 版本发布与固定 | D15: Recipe需合法签名、验证并由用户手动发布；空闲激活，运行/暂停任务固定原版本。 | E15: 不自动发版；不为联调关签名；APK升级遵守系统确认。 | F15: 手动发布、篡改拒绝、暂停中升级/回退证据。 | G15: 功能包负责人+验收人 | H15: 原计划约束保留；本版集中管理
A16: 门禁 | B16: G5 | C16: SIM公网实时视频 | D16: 真实视频、强制TURN relay、长时观看与重连；记录网络条件、授权和设备切换。 | E16: 截图轮询不能充当实时投屏；百台在线不等于百路视频。 | F16: 30分钟观看记录；实际fps/延迟及条件，不把设计默认当硬SLA。 | G16: 功能包负责人+验收人 | H16: 原计划约束保留；本版集中管理
... A44: 多智能体 | B44: MA-06 | C44: 等待时空槽回填 | D44: P14 任一路 WAIT_LOCK/WAIT_AUTH/WAIT_HARDWARE 时，从 P08 软件证据、P16/P40、P48 只读环境等 READY 池补位。 | E44: P08/P14 真机共用设备锁；P15 仍等待 P14；不得因补位扩展二期范围。 | F44: 被阻塞项、解除条件、补位 work item。 | G44: Root Worker | H44: 避免全局等待

Sheet 04_旧任务对照
A1: 04 / 120项原任务 → 新闭环包
A2: 只读迁移账本：完整保留原任务状态、进度证据、验收与契约。原表头“所有任务未实施”与D/N列不一致，本版采用D/N逐行记录；审阅表差异另行提示。每个旧T只有一个主归属，协同验收见新卡片。
A5: 原T | B5: 原任务名称 | C5: 原状态 | D5: 原负责人 | E5: 新包 | F5: 新包状态 | G5: 原进度 / 证据（原文） | H5: 迁移提醒 | I5: 原验收（原文） | J5: 原契约（原文） | K5: 原前置（只留痕） | L5: 原表位置 / 来源
A6: T001 | B6: P0｜锁定代码并跑真实基线 | C6: 已完成 | D6: AI Agent | E6: P00 | F6: ='01_闭环计划'!D6 | G6: 未提供证据记录 | H6: 沿用完成；仅补缺失证据，不重做。 | I6: 验收1：干净环境能复跑同一SHA 验收2：失败项逐条入01代码审阅 验收3：不把mock或编译成功写成真机发布成功 | J6: 基线失败与后续回归分开记录；本次没有实际运行上述工程命令。 | K6: 无 | L6: 原工作簿/02_实施任务!A6:O6；S31、S01
A7: T002 | B7: P0｜全仓覆盖和问题补录 | C7: 已完成 | D7: AI Agent | E7: P00 | F7: ='01_闭环计划'!D6 | G7: 未提供证据记录 | H7: 沿用完成；仅补缺失证据，不重做。 | I7: 验收1：每个一级目录都有审阅状态 验收2：新旧Bug可追溯 验收3：一期外代码变更有明确原因 | J7: 覆盖率指已审阅文件/已执行测试，不能用“全仓无报错”替代业务验收。 | K7: T001 | L7: 原工作簿/02_实施任务!A7:O7；S31、S01
A8: T003 | B8: P0｜写分层ADR并确定复用边界 | C8: 已完成 | D8: AI Agent | E8: P00 | F8: ='01_闭环计划'!D6 | G8: 未提供证据记录 | H8: 沿用完成；仅补缺失证据，不重做。 | I8: 验收1：同一设备不存在两套独立写锁 验收2：有新旧功能开关及回滚路线 验收3：所有任务能定位唯一状态来源 | J8: 旧PublishPlan/Target/提交账本不得另造并行发布事实；Edge仅开发诊断。 | K8: T001 | L8: 原工作簿/02_实施任务!A8:O8；S31、S02、S03
A9: T004 | B9: P1｜逐字段盘点及31项闲鱼目录覆盖 | C9: 待联调 | D9: ZCode | E9: P01 | F9: ='01_闭环计划'!D7 | G9: 2026-09-06 field-map.json 已生成；31项闲鱼目录保留原ID；发布/删除帖子 AVAILABILITY_PENDING。Web 101 tests passed。 | H9: 复用已有代码/测试；按新包验收，未提供的证据不推定通过。 | I9: 验收1：31项均有处理归属 验收2：没有开启但未消费的字段 验收3：旧blocked不作为永不实现的依据 | J9: 字段仅存库不算发布实现；平台不支持的字段须保留数据并给出明确不支持原因。 | K9: T001 | L9: 原工作簿/02_实施任务!A9:O9；S20、S18、S17
A10: T005 | B10: P1｜生产API真相与真实登录态 | C10: 待联调 | D10: ZCode | E10: P02 | F10: ='01_闭环计划'!D8 | G10: 2026-09-06 生产 404/501 不再写 localStorage；session 从 /api/v1/session 加载。product-catalog-fail-closed.spec.ts 通过。 | H10: 复用已有代码/测试；按新包验收，未提供的证据不推定通过。 | I10: 验收1：断API保存失败且无业务本地新增 验收2：低权限不能远控/发版 验收3：清空localStorage不丢真实业务数据 | J10: UI权限只改善体验，后端必须独立鉴权；生产API缺失不能自动写本地。 | K10: T001、T003 | L10: 原工作簿/02_实施任务!A10:O10；S08、S09、S24
A11: T006 | B11: P1｜统一设备/文件/版本发布权限 | C11: 待联调 | D11: ZCode | E11: P02 | F11: ='01_闭环计划'!D8 | G11: 2026-09-06 新增 device.control/task.create/recipe.publish/data.delete；test_phase1_permissions.py 通过。 | H11: 复用已有代码/测试；按新包验收，未提供的证据不推定通过。 | I11: 验收1：跨tenant请求404/403 验收2：设备A不能读B任务/素材 验收3：发版必须操作者身份及权限 | J11: 一期单租户运行也必须过跨租户测试；后续二期不需重建所有主键。 | K11: T003 | L11: 原工作簿/02_实施任务!A11:O11；S02、S04、S05
A12: T007 | B12: P1｜设备注册、重绑与凭据撤销 | C12: 待联调 | D12: ZCode | E12: P03 | F12: ='01_闭环计划'!D9 | G12: 2026-09-06 重绑撤销旧 Companion token 并递增 controlEpoch；test_reenroll_revokes_previous_companion_instance 通过。迁移 002_device_control_epoch.sql 待生产执行。 | H12: 复用已有代码/测试；按新包验收，未提供的证据不推定通过。 | I12: 验收1：重绑后旧token401 验收2：并发注册只有一个活跃实例 验收3：手机通过SIM能注册和心跳 | J12: POST /api/v1/mobile/enrollments与/companion/v2/enroll沿用；新字段须向后兼容。 | K12: T006 | L12: 原工作簿/02_实施任务!A12:O12；S04、S03、S05
A13: T008 | B13: P1｜自动探测真实设备系统与能力 | C13: 进行中 | D13: ZCode | E13: P04 | F13: ='01_闭环计划'!D10 | G13: 2026-09-06 heartbeat 增加 sdkInt/model/network/mediaProjection。2026-09-06 ADB 真机 OnePlus LE2100 / Android 14 / SDK 34。 Companion com.company.cloudctl.companion 0.1.0 versionCode=1 minSdk=29 targetSdk=35。 闲鱼 com.taobao.idlefish 7.27.90 versionCode=516。 小红书 com.xingin.xhs 8.50.1 versionCode=8501132。 基线机型是红米 Note9，当前连接的是 OnePlus 9R，不能冒充 Note9 验收。 | H13: 复用已有代码/测试；按新包验收，未提供的证据不推定通过。 | I13: 验收1：实际Note9有设备报告 验收2：断开权限后任务前置校验失败 验收3：WiFi/蜂窝切换真实反映 | J13: heartbeat增加可选字段兼容旧APK；capability不可用需reasonCode。 | K13: T007 | L13: 原工作簿/02_实施任务!A13:O13；S30、S25、S06
A14: T009 | B14: P1｜平台包/版本/账号能力自动探测 | C14: 待联调 | D14: ZCode | E14: P04 | F14: ='01_闭环计划'!D10 | G14: 2026-09-06 真机已安装闲鱼7.27.90、小红书8.50.1、Companion 0.1.0。 CommandV1 允许 com.xingin.xhs；mobile_service._insert_task 仍只允许 Companion/闲鱼，小红书任务下发未接通。2026-09-06 ADB 真机 OnePlus LE2100 / Android 14 / SDK 34。 Companion com.company.cloudctl.companion 0.1.0 versionCode=1 minSdk=29 targetSdk=35。 闲鱼 com.taobao.idlefish 7.27.90 versionCode=516。 小红书 com.xingin.xhs 8.50.1 versionCode=8501132。 基线机型是红米 Note9，当前连接的是 OnePlus 9R，不能冒充 Note9 验收。 | H14: 复用已有代码/测试；按新包验收，未提供的证据不推定通过。 | I14: 验收1：卸载/升级后正确上报 验收2：官方单开小红书可注册 验收3：未知包本地和后端都拒绝 | J14: 版本只是适配选择与证据，不作为用户必须知道的产品输入。 | K14: T008 | L14: 原工作簿/02_实施任务!A14:O14；S04、S29、S28
A15: T010 | B15: P1｜每平台唯一账号与换绑事务 | C15: 待联调 | D15: ZCode | E15: P03 | F15: ='01_闭环计划'!D9 | G15: 2026-09-06 同设备同平台仅一条 BOUND；闲鱼+小红书可并存。 换绑递增 bindingVersion，旧排队任务 ACCOUNT_CHANGED。 tests: test_one_bound_account_per_device_platform_and_history_preserved 与 test_rebind_fails_queued_task_with_account_changed 通过。 迁移 003_account_binding_ownership.sql 未应用到生产库。 | H15: 复用已有代码/测试；按新包验收，未提供的证据不推定通过。 | I15: 验收1：1闲鱼+1小红书通过 验收2：两个闲鱼账号不能同时BOUND 验收3：换绑后旧排队任务ACCOUNT_CHANGED | J15: 不保存平台登录密码；secretRef如旧模型必填，调整为适用授权方式的可选字段。 | K15: T009、T006 | L15: 原工作簿/02_实施任务!A15:O15；S02、S04、S03
A16: T011 | B16: P1｜账号换绑后的数据归属与旧任务阻断 | C16: 待联调 | D16: ZCode | E16: P03 | F16: ='01_闭环计划'!D9 | G16: 2026-09-06 Product/Post 仍是租户资产。任务/发布目标冻结 accountId、bindingVersion、deviceIdAtExecution。 GET /api/v1/accounts/{id}/ownership 可查已解绑账号历史。换绑不改写历史 accountId。 周期计划完整模型仍待 T017；当前对 DRAFT/SCHEDULED/QUEUED 发布计划暂停为 CANCELED。 | H16: 复用已有代码/测试；按新包验收，未提供的证据不推定通过。 | I16: 验收1：甲订单依然属于甲 验收2：乙无法误执行甲任务 验收3：历史设备与当前绑定都可解释 | J16: 账号历史保留不等于永不允许删除；用户删除有独立权限与引用策略。 | K16: T010 | L16: 原工作簿/02_实施任务!A16:O16；S02、S03
A17: T012 | B17: P0｜高层指令与强类型参数契约 | C17: 待联调 | D17: ZCode | E17: P01 | F17: ='01_闭环计划'!D7 | G17: 2026-09-06 CommandV1 schema contracts/phase1/command-v1.schema.json；Python/TS/Kotlin 同 fixture。 拒绝 shell/DEX/JS/未知字段。test_command_v1.py 通过。 Companion claim 路径仍发 cloudctl.mobile/v1 steps，尚未用 CommandV1 替换生产下发。 2026-09-08 生产claim已改为cloudctl.command/v1；Companion解析command并执行builtin Recipe。 | H17: 复用已有代码/测试；按新包验收，未提供的证据不推定通过。 | I17: 验收1：三端解析同fixture一致 验收2：错设备/错账号/错schema拒绝 验收3：云端命令不含未授权执行代码 | J17: 手机只消费冻结参数和已发布本地Recipe；动态任意shell/DEX/JS执行均不在协议中。 | K17: T003、T009、T004 | L17: 原工作簿/02_实施任务!A17:O17；S06、S29、S27
A18: T013 | B18: P0｜统一业务任务API与唯一状态源 | C18: 进行中 | D18: ZCode | E18: P05 | F18: ='01_闭环计划'!D11 | G18: 2026-09-06 新增 /api/v1/platform-tasks，映射 MobileTask，不另建队列。幂等双击返回原任务；deviceIds 生成独立 taskId 共享 batchId；游标分页。取消 QUEUED→CANCELLED；ACCOUNT_CHANGED 不可 retry。test_platform_tasks.py 通过。迁移 004 未上生产库。 | H18: 复用已有代码/测试；按新包验收，未提供的证据不推定通过。 | I18: 验收1：双击只建1任务 验收2：201条历史可分页查全 验收3：跨设备并行、同设备仅顺序执行 | J18: 新增/api/v1/platform-tasks；原/api/v1/mobile/tasks为底层兼容，不另建业务队列。 终态限定SUCCEEDED/FAILED/CANCELLED/EXPIRED；REMOTE不是业务任务终态。 | K18: T012、T010 | L18: 原工作簿/02_实施任务!A18:O18；S04、S03、S02
A19: T014 | B19: P1｜步骤事件、错误和结构化结果 | C19: 进行中 | D19: ZCode | E19: P05 | F19: ='01_闭环计划'!D11 | G19: 2026-09-06 事件增加 attemptId/stepId/receivedAt；PAUSE_* 不记 FAILED；错误 resultType 422。契约 contracts/phase1/events/task-event.schema.json。现有事件重放/缺口 409 仍有效。 | H19: 复用已有代码/测试；按新包验收，未提供的证据不推定通过。 | I19: 验收1：不同失败code保持原义 验收2：事件重放不乱序 验收3：错误resultType被422拒绝 | J19: UTC保存时间；业务时区仅调度解释；不信任设备时钟作为授权有效期唯一依据。 | K19: T013 | L19: 原工作簿/02_实施任务!A19:O19；S04、S06、S26
A20: T015 | B20: P1｜不可变业务快照和资源解析规则 | C20: 待联调 | D20: ZCode | E20: P06 | F20: ='01_闭环计划'!D12 | G20: 2026-09-06 PlatformTask 创建时冻结 commandPayload 并计算 snapshotSha256；retry 复用原 parameters，不读后续编辑。完整 PublishSnapshot 池/水印解析仍待发布链路接通。 | H20: 复用已有代码/测试；按新包验收，未提供的证据不推定通过。 | I20: 验收1：旧任务文案和媒体hash不漂移 验收2：相同任务重试不重新随机 验收3：快照可以独立复现要执行的内容 | J20: 默认地址选择：设备池优先、通用池回退；用户可配置。默认规则是设计值，不伪称用户已指定。 | K20: T013 | L20: 原工作簿/02_实施任务!A20:O20；S02、S03
A21: T016 | B21: P0｜所有设备写操作共用fencing租约 | C21: 待联调 | D21: ZCode | E21: P08 | F21: ='01_闭环计划'!D14 | G21: 2026-09-06 Companion claim 复用 DeviceLeaseRow，ownerType=AUTO；PAUSE_WAITING_USER 队头阻塞后项；maintenance 禁止 AUTO claim；心跳续租。test_paused_head_blocks_later_task_and_maintenance_blocks_auto_claim 通过。迁移 005 未上生产库。APK 本地单调时钟门禁仍待 Companion 执行器。 | H21: 复用已有代码/测试；按新包验收，未提供的证据不推定通过。 | I21: 验收1：同设备并发100次claim仅1writer 验收2：旧epoch命令拒绝 验收3：maintenance禁止AUTO 验收4：下载期间不丢租 | J21: 设计初值lease60秒/续租15秒，需配置与压测；暂停只读不需要自动化writer，但设备逻辑队列仍阻塞到恢复/取消。 | K21: T013、T007 | L21: 原工作簿/02_实施任务!A21:O21；S04、S02、S03
A22: T017 | B22: P1｜预约和周期产生独立任务 | C22: 待联调 | D22: ZCode | E22: P06 | F22: ='01_闭环计划'!D12 | G22: 2026-09-07 新增 /api/v1/task-schedules。ONCE/RECURRING 触发按 scheduleId+scheduledFor+deviceId 幂等生成独立 PlatformTask；关闭计划 409；10 设备 10 taskId；换绑暂停计划。test_task_schedules.py 通过。迁移 006 未上生产库。Temporal 工作流未接线，当前为 API 触发。 | H22: 复用已有代码/测试；按新包验收，未提供的证据不推定通过。 | I22: 验收1：重复消息不重复建任务 验收2：时区/DST测试 验收3：关闭计划不再触发 验收4：10设备生成10独立任务 | J22: 设计默认：发布startDeadline到点后30分钟；订单/采集可更宽。参数可调，不当用户已确认SLA。 | K22: T013、T015 | L22: 原工作簿/02_实施任务!A22:O22；S31、S02
A23: T018 | B23: P1｜统一立即/预约/周期表单 | C23: 待联调 | D23: ZCode | E23: P06 | F23: ='01_闭环计划'!D12 | G23: 2026-09-07 ScheduleEditor 统一 IMMEDIATE/ONCE/RECURRING；闲鱼简单任务/额外任务/采集页去掉仅立即执行的旧 select。schedule-editor.spec.ts 通过。刷新后预约仍在需 Control API 联调。 | H23: 复用已有代码/测试；按新包验收，未提供的证据不推定通过。 | I23: 验收1：刷新后预约仍在 验收2：10台创建结果显示10 taskId 验收3：每页使用同一调度DTO | J23: 不新增优先级UI；批量入口只是便捷创建独立任务。 | K23: T017、T005 | L23: 原工作簿/02_实施任务!A23:O23；S15、S16、S13
A24: T019 | B24: P0｜定义可签名的手机本地状态图包 | C24: 待联调 | D24: ZCode | E24: P07 | F24: ='01_闭环计划'!D13 | G24: 2026-09-07 Recipe 签名包 schema + validate_recipe_package。test_recipe_package.py 通过。 | H24: 复用已有代码/测试；按新包验收，未提供的证据不推定通过。 | I24: 验收1：伪造/篡改/不兼容包拒绝 验收2：状态图有界 验收3：全部动作在APK白名单中 | J24: 原生新能力需要APK升级；页面和流程变化可更新数据Recipe；不开放任意远程代码执行。 | K24: T012、T003 | L24: 原工作簿/02_实施任务!A24:O24；S02、S27、S29
A25: T020 | B25: P0｜本地Recipe解释器与平台注册 | C25: 进行中 | D25: ZCode | E25: P07 | F25: ='01_闭环计划'!D13 | G25: 2026-09-07 Companion RecipeEngine 本地解释；gradle testDebugUnitTest 通过。生产 claim 仍兼容旧 steps。 2026-09-08 生产领取主入口不再发旧steps（legacyStepsEnabled默认false）。 | H25: 复用已有代码/测试；按新包验收，未提供的证据不推定通过。 | I25: 验收1：同命令独立本地完成流程 验收2：循环不会无限跑 验收3：未知页面进WAITING_USER 验收4：错recipe hash拒绝 | J25: 旧low-level steps用兼容adapter，不继续扩成第二套主引擎。 | K25: T019、T009 | L25: 原工作簿/02_实施任务!A25:O25；S27、S28、S29
A26: T021 | B26: P1｜执行生命周期、启动和下载错误修复 | C26: 待联调 | D26: ZCode | E26: P07 | F26: ='01_闭环计划'!D13 | G26: 2026-09-07 claim 后先心跳续租再下素材；launchTargetApp；锁屏/存储/无障碍 preflight；CancellationException 记 CANCELLED；ExecutorFailure.code 保留。gradle testDebugUnitTest 通过。 | H26: 复用已有代码/测试；按新包验收，未提供的证据不推定通过。 | I26: 验收1：手机桌面能启动平台 验收2：下载异常不卡RUNNING 验收3：取消不伪装失败 验收4：缺权限不会盲跑 | J26: 常亮执行是用户环境，不等于永不崩溃；不承诺自动解锁PIN或绕过系统权限。 | K26: T020、T016、T014 | L26: 原工作簿/02_实施任务!A26:O26；S25、S28、S26
A27: T022 | B27: P1｜独立事件和结果上传协程 | C27: 待联调 | D27: ZCode | E27: P07 | F27: ='01_闭环计划'!D13 | G27: 2026-09-07 独立 outboxLoop；dueEventsByTask 按任务交错上传；成功结果含 outcome/resultType；401 永久停发。 | H27: 复用已有代码/测试；按新包验收，未提供的证据不推定通过。 | I27: 验收1：长任务运行时Web及时收到steps 验收2：重连顺序正确 验收3：成功结果不是{} | J27: 仅日志可最终一致；设备控制租约和不可逆动作门禁不能等日志慢慢补。 | K27: T014、T021 | L27: 原工作簿/02_实施任务!A27:O27；S25、S26
A28: T023 | B28: P0｜持久化可恢复检查点 | C28: 待联调 | D28: ZCode | E28: P08 | F28: ='01_闭环计划'!D14 | G28: 2026-09-07 task_checkpoint 表；重启 RUNNING→RESUME_CHECK 不再 FAILED_RESTART。AutomationStoreTest checkpoint 用例通过。 | H28: 复用已有代码/测试；按新包验收，未提供的证据不推定通过。 | I28: 验收1：同taskId从检查点继续 验收2：第N项恢复不重做前N-1项 验收3：版本不匹配停下 | J28: 检查点不是屏幕截图；必须包含能判定恢复安全性的业务状态。 | K28: T020、T022、T015 | L28: 原工作簿/02_实施任务!A28:O28；S26、S27
A29: T024 | B29: P0｜发布/消耗/删除提交门禁 | C29: 待联调 | D29: ZCode | E29: P09 | F29: ='01_闭环计划'!D15 | G29: 2026-09-07 action_journal INTENT/APPLIED/UNKNOWN；同 actionKey APPLIED 不再二次点击。单元测试覆盖。真机断网二次提交仍待联调。 | H29: 复用已有代码/测试；按新包验收，未提供的证据不推定通过。 | I29: 验收1：点击发布后断网不自动再发 验收2：预算/参数变化必须重新确认 验收3：已有成功item不重复处理 | J29: 不宣称第三方UI严格exactly-once；采用可判定防重+不确定结果核对。 | K29: T023、T016 | L29: 原工作簿/02_实施任务!A29:O29；S31、S04、S26
A30: T025 | B30: P1｜不确定外部结果核对 | C30: 待联调 | E30: P09 | F30: ='01_闭环计划'!D15 | G30: 未提供证据记录 2026-09-08 服务端UNKNOWN/RECONCILING/终态ack门禁单测已补；真机断网二次提交仍无。 | H30: 复用已有代码/测试；按新包验收，未提供的证据不推定通过。 | I30: 验收1：未知状态不会自动变成功 验收2：有结果可收敛 验收3：所有人工核对可审计 | J30: 确认未成功不是无证据强制重试；平台没有可靠身份时保留不确定状态。 | K30: T024 | L30: 原工作簿/02_实施任务!A30:O30；S31、S26
A31: T026 | B31: P0｜暂停请求与安全停止握手 | C31: 已完成 | D31: ZCode | E31: P08 | F31: ='01_闭环计划'!D14 | G31: 真机联调通过 2026-09-07 任务: 54548b87-1963-40ad-a188-3f991e78f04b 状态: PAUSED_WAITING_USER, pauseAckAt=2026-09-07T15:20:52.082937Z, controlMode=REMOTE 后续任务被挡: 850060b6-649a-4573-aa6a-9cd3b9d82647 停在QUEUED 代码: CompanionSyncService心跳前移到预检; AndroidManifest补queries; launchTargetApp兜底 APK: 已编译签名安装 /tmp/cloudctl-app-debug-signed.apk 设备: OnePlus9R b0644fb5, 闲鱼未点发布 | H31: 沿用完成；仅补缺失证据，不重做。 | I31: 验收1：自动任务运行时看屏不暂停 验收2：接管前自动化确已停 验收3：暂停后后续队列不越过 | J31: 控制消息可独立于长任务主循环接收；只读观看不触发pause。 | K31: T023、T016 | L31: 原工作簿/02_实施任务!A31:O31；S04、S27、S26
A32: T027 | B32: P0｜交还控制权并继续原任务 | C32: 进行中 | D32: ZCode | E32: P08 | F32: ='01_闭环计划'!D14 | G32: 2026-09-07 接 T026：同 taskId 从检查点继续；心跳下发 RESUME；新 AUTO epoch；pageVerified=false 拒绝；不从步骤1重跑。真机恢复尚未验收。 2026-09-08 API：resume须ack；取消不可恢复。真机恢复在CommandV1路径上待补一轮。 | H32: 复用已有代码/测试；按新包验收，未提供的证据不推定通过。 | I32: 验收1：处理后继续同taskId 验收2：旧远控命令不落地 验收3：无法判定不盲目恢复 | J32: 可以自动回到安全锚点，但不能为恢复随意丢弃人工内容或重复提交。 | K32: T026、T025、T011 | L32: 原工作簿/02_实施任务!A32:O32；S26、S27
A33: T028 | B33: P1｜统一任务队列、详情与恢复入口 | C33: 进行中 | E33: P05 | F33: ='01_闭环计划'!D11 | G33: 未提供证据记录 | H33: 复用已有代码/测试；按新包验收，未提供的证据不推定通过。 | I33: 验收1：所有任务页复用同状态组件 验收2：暂停与失败视觉区分 验收3：刷新不丢历史 | J33: 长期任务历史可查；无父任务状态；batchId仅过滤。 | K33: T013、T014、T026、T027、T018 | L33: 原工作簿/02_实施任务!A33:O33；S04、S20
A34: T029 | B34: P0｜设备主动联网的WebRTC会话服务 | C34: 未开始 | E34: P10 | F34: ='01_闭环计划'!D16 | G34: 未提供证据记录 | H34: 复用已有代码/测试；按新包验收，未提供的证据不推定通过。 | I34: 验收1：SIM网络可建立relay视频 验收2：跨租户信令403 验收3：TURN凭据过期不可继续新建会话 | J34: POST /devices/{id}/rtc-sessions；WSS signaling；TURN REST短期凭据。接口名称为建议，优先复用现有路由规范。 | K34: T006、T007 | L34: 原工作簿/02_实施任务!A34:O34；S35、S36、S31
A35: T030 | B35: P0｜MediaProjection实时采集与前台服务 | C35: 未开始 | E35: P10 | F35: ='01_闭环计划'!D16 | G35: 未提供证据记录 | H35: 复用已有代码/测试；按新包验收，未提供的证据不推定通过。 | I35: 验收1：有授权可连续视频 验收2：拒绝授权不崩溃不假在线 验收3：进程死亡后重新授权路径明确 | J35: CaptureState=IDLE/NEEDS_CONSENT/ACTIVE/STOPPED/ERROR；真实能力上报。 | K35: T008、T029 | L35: 原工作簿/02_实施任务!A35:O35；S32、S37、S30
