Workbook

Sheet 00_需求与架构
A1: LAMDA-YUN / 一期审阅与实施交接
A2: 2026-09-06 · 已确认需求版 · 3个Sheet · 代码审阅 / 架构边界 / 智能体任务
A3: 审阅基准：b394475c56a07b0ea660531222d182646e1c7e66。公开源码静态复核；git clone因DNS失败，未运行工程构建、服务、数据库或Android真机。此文件不构成“全部Bug已穷尽”的承诺。
A5: 审阅记录 | C5: 其中：静态确认 | E5: 实施任务 | G5: 任务完成率
A6: =COUNTA('01_代码审阅'!$A$6:$A$68) | C6: =COUNTIF('01_代码审阅'!$C$6:$C$68,"静态确认") | E6: =COUNTA('02_实施任务'!$A$6:$A$125) | G6: =IFERROR(COUNTIF('02_实施任务'!$D$6:$D$125,"已完成")/COUNTA('02_实施任务'!$A$6:$A$125),0)
A9: 怎么使用这份交接文件
A10: 先看本页的已确认需求与设计默认，再按02表T编号执行。编号已按依赖排序；允许分工，但不能跳过依赖和设备单写锁约束。
A11: 蓝底“状态/负责人/证据”列用于维护进度。代码写完先标待联调或待真机；必须补测试日志、commit与真实任务证据后才能标已完成。
A12: 63条包括25条静态确认、22条需求差距、10条待复现风险、4条待验证约束、2条旧稿纠正。不要把它们合称63个已复现Bug。
A13: 120项任务共960个具体步骤。每行步骤1–4与5–8需一起执行；伴随Markdown为同一数据，可复制单项或整份交给智能体。
A14: 本版覆盖并修正旧稿：实时视频必做、同task恢复、手动发布Recipe、长期保存、Redmi Note9、每平台独立账号和31项闲鱼目录。
A16: 阶段进度 / 自动统计状态列
A17: 阶段 | B17: 任务数 | C17: 已完成 | D17: 进行中 | E17: 待联调 | F17: 待真机 | G17: 待验收 | H17: 阻塞
A18: A 基线与身份 | B18: =COUNTIF('02_实施任务'!$B$6:$B$125,A18) | C18: =COUNTIFS('02_实施任务'!$B$6:$B$125,$A18,'02_实施任务'!$D$6:$D$125,"已完成") | D18: =COUNTIFS('02_实施任务'!$B$6:$B$125,$A18,'02_实施任务'!$D$6:$D$125,"进行中") | E18: =COUNTIFS('02_实施任务'!$B$6:$B$125,$A18,'02_实施任务'!$D$6:$D$125,"待联调") | F18: =COUNTIFS('02_实施任务'!$B$6:$B$125,$A18,'02_实施任务'!$D$6:$D$125,"待真机") | G18: =COUNTIFS('02_实施任务'!$B$6:$B$125,$A18,'02_实施任务'!$D$6:$D$125,"待验收") | H18: =COUNTIFS('02_实施任务'!$B$6:$B$125,$A18,'02_实施任务'!$D$6:$D$125,"阻塞")
A19: B 任务与执行 | B19: =COUNTIF('02_实施任务'!$B$6:$B$125,A19) | C19: =COUNTIFS('02_实施任务'!$B$6:$B$125,$A19,'02_实施任务'!$D$6:$D$125,"已完成") | D19: =COUNTIFS('02_实施任务'!$B$6:$B$125,$A19,'02_实施任务'!$D$6:$D$125,"进行中") | E19: =COUNTIFS('02_实施任务'!$B$6:$B$125,$A19,'02_实施任务'!$D$6:$D$125,"待联调") | F19: =COUNTIFS('02_实施任务'!$B$6:$B$125,$A19,'02_实施任务'!$D$6:$D$125,"待真机") | G19: =COUNTIFS('02_实施任务'!$B$6:$B$125,$A19,'02_实施任务'!$D$6:$D$125,"待验收") | H19: =COUNTIFS('02_实施任务'!$B$6:$B$125,$A19,'02_实施任务'!$D$6:$D$125,"阻塞")
A20: C 视频与远控 | B20: =COUNTIF('02_实施任务'!$B$6:$B$125,A20) | C20: =COUNTIFS('02_实施任务'!$B$6:$B$125,$A20,'02_实施任务'!$D$6:$D$125,"已完成") | D20: =COUNTIFS('02_实施任务'!$B$6:$B$125,$A20,'02_实施任务'!$D$6:$D$125,"进行中") | E20: =COUNTIFS('02_实施任务'!$B$6:$B$125,$A20,'02_实施任务'!$D$6:$D$125,"待联调") | F20: =COUNTIFS('02_实施任务'!$B$6:$B$125,$A20,'02_实施任务'!$D$6:$D$125,"待真机") | G20: =COUNTIFS('02_实施任务'!$B$6:$B$125,$A20,'02_实施任务'!$D$6:$D$125,"待验收") | H20: =COUNTIFS('02_实施任务'!$B$6:$B$125,$A20,'02_实施任务'!$D$6:$D$125,"阻塞")
A21: D 版本与发布 | B21: =COUNTIF('02_实施任务'!$B$6:$B$125,A21) | C21: =COUNTIFS('02_实施任务'!$B$6:$B$125,$A21,'02_实施任务'!$D$6:$D$125,"已完成") | D21: =COUNTIFS('02_实施任务'!$B$6:$B$125,$A21,'02_实施任务'!$D$6:$D$125,"进行中") | E21: =COUNTIFS('02_实施任务'!$B$6:$B$125,$A21,'02_实施任务'!$D$6:$D$125,"待联调") | F21: =COUNTIFS('02_实施任务'!$B$6:$B$125,$A21,'02_实施任务'!$D$6:$D$125,"待真机") | G21: =COUNTIFS('02_实施任务'!$B$6:$B$125,$A21,'02_实施任务'!$D$6:$D$125,"待验收") | H21: =COUNTIFS('02_实施任务'!$B$6:$B$125,$A21,'02_实施任务'!$D$6:$D$125,"阻塞")
A22: E 素材与资源池 | B22: =COUNTIF('02_实施任务'!$B$6:$B$125,A22) | C22: =COUNTIFS('02_实施任务'!$B$6:$B$125,$A22,'02_实施任务'!$D$6:$D$125,"已完成") | D22: =COUNTIFS('02_实施任务'!$B$6:$B$125,$A22,'02_实施任务'!$D$6:$D$125,"进行中") | E22: =COUNTIFS('02_实施任务'!$B$6:$B$125,$A22,'02_实施任务'!$D$6:$D$125,"待联调") | F22: =COUNTIFS('02_实施任务'!$B$6:$B$125,$A22,'02_实施任务'!$D$6:$D$125,"待真机") | G22: =COUNTIFS('02_实施任务'!$B$6:$B$125,$A22,'02_实施任务'!$D$6:$D$125,"待验收") | H22: =COUNTIFS('02_实施任务'!$B$6:$B$125,$A22,'02_实施任务'!$D$6:$D$125,"阻塞")
A23: F 产品与帖子 | B23: =COUNTIF('02_实施任务'!$B$6:$B$125,A23) | C23: =COUNTIFS('02_实施任务'!$B$6:$B$125,$A23,'02_实施任务'!$D$6:$D$125,"已完成") | D23: =COUNTIFS('02_实施任务'!$B$6:$B$125,$A23,'02_实施任务'!$D$6:$D$125,"进行中") | E23: =COUNTIFS('02_实施任务'!$B$6:$B$125,$A23,'02_实施任务'!$D$6:$D$125,"待联调") | F23: =COUNTIFS('02_实施任务'!$B$6:$B$125,$A23,'02_实施任务'!$D$6:$D$125,"待真机") | G23: =COUNTIFS('02_实施任务'!$B$6:$B$125,$A23,'02_实施任务'!$D$6:$D$125,"待验收") | H23: =COUNTIFS('02_实施任务'!$B$6:$B$125,$A23,'02_实施任务'!$D$6:$D$125,"阻塞")
A24: G 小红书发布 | B24: =COUNTIF('02_实施任务'!$B$6:$B$125,A24) | C24: =COUNTIFS('02_实施任务'!$B$6:$B$125,$A24,'02_实施任务'!$D$6:$D$125,"已完成") | D24: =COUNTIFS('02_实施任务'!$B$6:$B$125,$A24,'02_实施任务'!$D$6:$D$125,"进行中") | E24: =COUNTIFS('02_实施任务'!$B$6:$B$125,$A24,'02_实施任务'!$D$6:$D$125,"待联调") | F24: =COUNTIFS('02_实施任务'!$B$6:$B$125,$A24,'02_实施任务'!$D$6:$D$125,"待真机") | G24: =COUNTIFS('02_实施任务'!$B$6:$B$125,$A24,'02_实施任务'!$D$6:$D$125,"待验收") | H24: =COUNTIFS('02_实施任务'!$B$6:$B$125,$A24,'02_实施任务'!$D$6:$D$125,"阻塞")
A25: H 闲鱼全功能 | B25: =COUNTIF('02_实施任务'!$B$6:$B$125,A25) | C25: =COUNTIFS('02_实施任务'!$B$6:$B$125,$A25,'02_实施任务'!$D$6:$D$125,"已完成") | D25: =COUNTIFS('02_实施任务'!$B$6:$B$125,$A25,'02_实施任务'!$D$6:$D$125,"进行中") | E25: =COUNTIFS('02_实施任务'!$B$6:$B$125,$A25,'02_实施任务'!$D$6:$D$125,"待联调") | F25: =COUNTIFS('02_实施任务'!$B$6:$B$125,$A25,'02_实施任务'!$D$6:$D$125,"待真机") | G25: =COUNTIFS('02_实施任务'!$B$6:$B$125,$A25,'02_实施任务'!$D$6:$D$125,"待验收") | H25: =COUNTIFS('02_实施任务'!$B$6:$B$125,$A25,'02_实施任务'!$D$6:$D$125,"阻塞")
A26: I 订单与统计 | B26: =COUNTIF('02_实施任务'!$B$6:$B$125,A26) | C26: =COUNTIFS('02_实施任务'!$B$6:$B$125,$A26,'02_实施任务'!$D$6:$D$125,"已完成") | D26: =COUNTIFS('02_实施任务'!$B$6:$B$125,$A26,'02_实施任务'!$D$6:$D$125,"进行中") | E26: =COUNTIFS('02_实施任务'!$B$6:$B$125,$A26,'02_实施任务'!$D$6:$D$125,"待联调") | F26: =COUNTIFS('02_实施任务'!$B$6:$B$125,$A26,'02_实施任务'!$D$6:$D$125,"待真机") | G26: =COUNTIFS('02_实施任务'!$B$6:$B$125,$A26,'02_实施任务'!$D$6:$D$125,"待验收") | H26: =COUNTIFS('02_实施任务'!$B$6:$B$125,$A26,'02_实施任务'!$D$6:$D$125,"阻塞")
A27: J 联调与验收 | B27: =COUNTIF('02_实施任务'!$B$6:$B$125,A27) | C27: =COUNTIFS('02_实施任务'!$B$6:$B$125,$A27,'02_实施任务'!$D$6:$D$125,"已完成") | D27: =COUNTIFS('02_实施任务'!$B$6:$B$125,$A27,'02_实施任务'!$D$6:$D$125,"进行中") | E27: =COUNTIFS('02_实施任务'!$B$6:$B$125,$A27,'02_实施任务'!$D$6:$D$125,"待联调") | F27: =COUNTIFS('02_实施任务'!$B$6:$B$125,$A27,'02_实施任务'!$D$6:$D$125,"待真机") | G27: =COUNTIFS('02_实施任务'!$B$6:$B$125,$A27,'02_实施任务'!$D$6:$D$125,"待验收") | H27: =COUNTIFS('02_实施任务'!$B$6:$B$125,$A27,'02_实施任务'!$D$6:$D$125,"阻塞")
A29: 01 / 已确认需求（后续模型不得自行改写）
A30: R01 | B30: 规模｜一期至少10台，面向百台扩展 | D30: 区分在线数、运行任务数和同时观看数；百台在线不等于百路高码率视频。 | G30: 用户已确认
A31: R02 | B31: 连接｜SIM移动网络连接 | D31: APK主动连接公网云端；手机和电脑不需同局域网。生产执行不依赖USB、ADB常驻或Edge Gateway。 | G31: 用户已确认
A32: R03 | B32: 视频｜流畅实时视频是一期必做 | D32: 画面流畅优先，不追求最高分辨率；截图轮询仅作诊断/降级，不能作为实时投屏验收。 | G32: 用户已确认
A33: R04 | B33: 远控｜观看不中断，写操作先接管 | D33: 点击、滑动、长按、文字输入、返回/Home/多任务；观看任务不占写锁，接管先暂停自动化。 | G33: 用户已确认
A34: R05 | B34: 恢复｜人工处理后继续原任务 | D34: 未知页面保留现场并暂停；交回控制权后校验页面与检查点，再继续原taskId。取消和暂停必须分开。 | G34: 用户已确认
A35: R06 | B35: 兼容｜红米Note9作为真实设备基线 | D35: 不猜Android版本。APK自动上报SDK/ROM/目标App版本；用户不用手填。手机常亮，允许无障碍、投屏授权和前台服务。 | G35: 用户已确认
A36: R07 | B36: 解耦｜云端负责做什么，APK负责怎么做 | D36: 云端负责内容、素材、业务快照、队列、定时、指令、状态；手机本地负责识别、动作、分支、采集和恢复。 | G36: 用户已确认
A37: R08 | B37: 更新｜APK整体升级+Recipe独立更新 | D37: 新版本生成并测试后，由用户在后台点击发布；未发布不可生效。运行中任务固定原版本。 | G37: 用户已确认
A38: R09 | B38: 队列｜立即/预约/周期；每设备串行FIFO | D38: 闲鱼与小红书共享同台设备写队列；不做优先级。多设备操作生成独立任务，不新增父任务状态。 | G38: 用户已确认
A39: R10 | B39: 账号｜每设备1闲鱼+1小红书，可解绑换绑 | D39: 两平台各自绑定。历史订单、发布实例、任务和统计归原账号；换绑不迁移历史。云端待发布内容库可复用。 | G39: 用户已确认
A40: R11 | B40: 异常｜已知弹窗处理，未知暂停等人工 | D40: 登录失效、人机验证、风控及未知页面暂停并提供接管入口；不自动绕过平台或系统的验证/授权。 | G40: 用户已确认
A41: R12 | B41: 文件｜图片/视频上传、下发与使用 | D41: 素材必须云端持久化并下载到手机供发布；支持文件推送、截图保存和复制粘贴。剪贴板按系统授权边界实现。 | G41: 用户已确认
... A49: R20 | B49: 范围｜不加入未要求的二期业务 | D49: 不扩到转转、抖音、公众号、采购、自动客服等。旧入口不应伪装为一期可用；真实缺口列出证据。 | G49: 按原始范围约束
A51: 02 / 本稿设计默认（与用户已确认需求区分）
A52: D01 | B52: 技术分层 | D52: 保留模块化Control API及既有Temporal/租约/发布账本；本地签名声明式状态图+Kotlin原语。 | G52: 用户确认云端/手机解耦；具体状态图技术为本稿设计。
A53: D02 | B53: 视频起点 | D53: MediaProjection+WebRTC+TURN；建议默认720p约20fps、自适应15–30fps，以流畅为先。 | G53: 数值不是用户硬指标；正式验收必须写明网络条件和测量口径。
...

Sheet 01_代码审阅
A1: 01 / 代码审阅与需求差距
A2: P0：主链路/数据/并发安全阻塞；P1：一期关键功能与稳定性；P2：质量与验证约束。静态确认不等于已经真机复现。
A3: 请先按“结论类型”筛选：风险须先复现；需求差距须实现；旧稿纠正不是新增Bug。来源S编号见00表来源索引，源码链接固定本次SHA。
A5: 编号 | B5: 级别 | C5: 结论类型 | D5: 状态 | E5: 负责人 | F5: 模块 | G5: 问题 / 缺口 | H5: 源码证据 / 函数位置 | I5: 复现 / 核查方法 | J5: 修复指导 | K5: 验收测试 | L5: 关联任务 | M5: 修复提交 / 验收证据 | N5: 来源编号
A6: B001 | B6: P0 | C6: 静态确认 | D6: 代码已修/待联调 | E6: ZCode | F6: 商品/数据库 | G6: 商品分组写错外键对象 | H6: services.py batch_update_product_group/import_products 写 content_id=product_id；db.py 的content_id外键指向content_item。 | I6: 在开启FK的数据库建1商品+1内容组；执行批量分组；检查FK异常或错误关联。 | J6: 新增ProductGroup/ProductGroupMembership，FK指向product；迁移旧groupName与可识别脏数据；禁止复用帖子membership。 | K6: Postgres/SQLite FK开启均成功；分组删改不影响帖子；无孤儿行。 | L6: T058、T060 | N6: S02、S03
A7: B002 | B7: P1 | C7: 静态确认 | D7: 未处理 | F7: 商品/价格 | G7: 字符串价格用于数值范围筛选 | H7: ProductRow.price=String；filter_products直接price >= min_price / <= max_price。 | I7: 录入9.9/20/100/1000；查询20至100区间；核对结果。 | J7: 迁移price_cents BIGINT；Decimal转换，保留API兼容输出；范围过滤使用数值且None判断。 | K7: 20至100只返回20和100；0/小数/非法数值边界覆盖。 | L7: T058、T059 | N7: S03、S02
A8: B003 | B8: P1 | C8: 静态确认 | D8: 未处理 | F8: 商品/删除 | G8: 批量删除绕过单项引用保护 | H8: archive_product检查活跃PublishPlan；batch_delete_products直接ARCHIVED。 | I8: 建引用商品的活动发布计划；分别单删和批删，比较行为。 | J8: 抽取统一归档保护并锁行；批量预检后同事务执行；返回blockedIds。 | K8: 单删批删同规则；任何被引用项导致整批不改；重复归档有明确幂等语义。 | L8: T059 | N8: S02
A9: B004 | B9: P1 | C9: 静态确认 | D9: 代码已修/待联调 | E9: ZCode | F9: Web数据 | G9: 404/501自动转localStorage造成真假数据分裂 | H9: product-catalog/post-catalog的isMissingApi触发usingLocal并保存本地。 | I9: API模式把保存接口改成404；保存后直接查询数据库。 | J9: 生产环境失败即报错；仅显式dev mock允许本地；删除会话内隐式降级。 | K9: 生产404不显示成功、不写业务localStorage；切换浏览器数据一致。 | L9: T005 | N9: S08、S09
A10: B005 | B10: P1 | C10: 静态确认 | D10: 代码已修/待联调 | E10: ZCode | F10: 商品/批删 | G10: 批删失败回退条件反向且可能部分删除 | H10: product-catalog.archive 在非404/501错误时逐个archive；404/501却转本地。 | I10: 批删返回409或500；观察是否仍发N个单删请求。 | J10: 禁止在权限/冲突/500后继续副作用请求；只对显式协商的接口兼容版本选路径。 | K10: 409/500后0个单删；批量失败无部分成功假象。 | L10: T062 | N10: S08
A11: B006 | B11: P1 | C11: 静态确认 | D11: 代码已修/待联调 | E11: ZCode | F11: 商品/复制 | G11: 复制商品丢失媒体资产关联 | H11: product-catalog.duplicate固定mediaAssetIds:[]。 | I11: 复制有两图商品；比较新商品mediaAssetIds。 | J11: 复用已完成资产ID和顺序，不复制blob；明确封面与引用计数。 | K11: 复制后原件/副本都可预览发布，删除一方不误删共享媒体。 | L11: T062 | N11: S08
A12: B007 | B12: P1 | C12: 静态确认 | D12: 代码已修/待联调 | E12: ZCode | F12: 商品/媒体 | G12: 新媒体没有进入MediaAsset链路 | H12: ProductEditView 新图进attributes.images，视频为blob URL；save保留旧mediaAssetIds。 | I12: 上传新图片/视频保存后刷新，检查服务端媒体关联与手机manifest。 | J12: 统一上传create/upload/complete；存assetId；草稿预览URL与业务引用分离。 | K12: 刷新与换电脑可见，APK下载hash一致，payload无data/blob URL。 | L12: T044、T061 | N12: S10
A13: B008 | B13: P1 | C13: 静态确认 | D13: 未处理 | F13: 商品/字段 | G13: 分组名和商品类别混用 | H13: ProductEditView.applyProduct用category补groupName；save用groupName写category。 | I13: 改分组保存；检查category是否被覆盖。 | J13: 独立category与groupId；迁移需报告不确定记录，不能盲目改全部category。 | K13: 分组重命名不改变类别；筛选类别和分组相互独立。 | L13: T058、T061 | N13: S10、S19
A14: B009 | B14: P1 | C14: 待复现风险 | D14: 未处理 | F14: 商品/路由 | G14: 编辑页切到新建可能沿用旧current.id | H14: loadProduct无id时resetForm未清current；save优先current.value.id。 | I14: 同组件路由先?id=A，再去无id新建；保存，检查是否覆盖A。 | J14: 新建分支清current/id/SPU；异步加载加request epoch，旧响应不覆盖新路由。 | K14: 从编辑转新建创建B，A不变；快速切A/B不串数据。 | L14: T061 | N14: S10
A15: B010 | B15: P1 | C15: 静态确认 | D15: 未处理 | F15: 商品/导入 | G15: 导入逐行保存，失败会部分写入 | H15: ProductImportView.importRows循环await catalog.save；无批次事务或结果账。 | I15: 100行第50行注入错误；重试并观察重复与已写入行。 | J15: 改预检+批次提交+幂等导入；每行错误带rowNo；已提交批次重复返回原结果。 | K15: 错误行可定位；重试不重复；UI准确展示已写入/失败数量。 | L15: T063、T064、T065 | N15: S11
A16: B011 | B16: P1 | C16: 静态确认 | D16: 未处理 | F16: 商品/分组 | G16: 分组CRUD仍是浏览器本地事实 | H16: data/product-groups.ts 使用本地持久化；ProductImportView调用createProductGroup。 | I16: 浏览器A建组，浏览器B同账号查询。 | J16: ProductGroup API为唯一真相；一次性导入旧数据，不长期双写。 | K16: 跨浏览器一致；API失败不能本地伪成功。 | L16: T060 | N16: S19、S11
A17: B012 | B17: P1 | C17: 静态确认 | D17: 代码已修/待联调 | E17: ZCode | F17: 帖子/删除 | G17: API模式的删除只写localStorage | H17: post-catalog.remove没有archive请求，只list/filter/saveLocal。 | I17: 删除帖子后直接GET内容API并刷新页面。 | J17: 复用archive_content API，后端成功再刷新query；批量定义原子性。 | K17: 刷新不复活，另一个浏览器看不到已归档项。 | L17: T067、T069 | N17: S09、S02
A18: B013 | B18: P1 | C18: 静态确认 | D18: 未处理 | F18: 帖子/标题 | G18: 新增revision未同步列表使用的title | H18: post-catalog保存已有帖只createRevision(payload)；add_revision未更新ContentItem.title。 | I18: 改标题A为B；比较保存后列表、详情和revision。 | J18: 标题写入revision并同事务维护列表摘要字段；加expectedRevision。 | K18: 三处标题一致；并发编辑后写方获409。 | L18: T067 | N18: S09、S02
A19: B014 | B19: P2 | C19: 静态确认 | D19: 未处理 | F19: 帖子/性能 | G19: 帖子列表额外N次HTTP请求 | H19: post-catalog.list先contents再Promise.all每项content。 | I19: 100帖子加载抓网络请求数。 | J19: 分页API直接给最新revision摘要、封面与分组；删除逐条GET。 | K19: 单页HTTP请求常数级，分页边界正确。 | L19: T067、T069 | N19: S09
A20: B015 | B20: P1 | C20: 静态确认 | D20: 代码已修/待联调 | E20: ZCode | F20: 帖子/媒体 | G20: 帖子图片/视频只存浏览器表示 | H20: PostEditorView图片compressImageFile，视频URL.createObjectURL。 | I20: 保存有视频笔记后换浏览器，创建手机发布任务。 | J20: 复用MediaAsset上传，revision保存媒体顺序/封面/类型。 | K20: 帖子素材跨端可用，任务使用固定asset版本。 | L20: T044、T068 | N20: S12
A21: B016 | B21: P2 | C21: 静态确认 | D21: 未处理 | F21: 商品/性能 | G21: 商品列表全量读取且逐商品查媒体 | H21: services.py list_products/filter_products对每个商品查询ProductMedia，未提供分页结果。 | I21: 1000商品执行列表；记录SQL计数与返回条数。 | J21: 增加稳定排序分页和批量媒体join；限制pageSize；Web不取全量再分页。 | K21: 1页<=100条；SQL次数不随页内商品数线性增长。 | L21: T059、T062 | N21: S02
A22: B017 | B22: P1 | C22: 需求差距 | D22: 未处理 | F22: 小红书/发布 | G22: 小红书发布页面只保存本地计划 | H22: PostPublishView.createTask没有API创建任务，提示不下发手机。 | I22: 点击创建，查看Network和服务端任务列表。 | J22: 统一xhs.publish_note命令、快照、媒体delivery和真实任务状态。 | K22: 网页→手机→发布结果/证据闭环，刷新保持历史。 | L22: T071、T076 | N22: S13
A23: B018 | B23: P1 | C23: 需求差距 | D23: 未处理 | F23: 闲鱼/发布 | G23: 发布商品页面没有下发真实任务 | H23: XianyuPublishGoodsView.createTask调用save/record并明确不会下发。 | I23: 创建发布任务，确认服务端无对应任务。 | J23: 改统一任务API；前端仅传业务参数，不生成UI步骤。 | K23: 后台存在独立taskId，APK收到正确商品快照。 | L23: T078、T081 | N23: S14
A24: B019 | B24: P1 | C24: 需求差距 | D24: 未处理 | F24: 闲鱼/基础任务 | G24: 擦亮/上下架/删除/绑定仍为本地任务 | H24: XianyuSimpleTaskView.createTask只saveSimpleConfig/recordSimpleTask。 | I24: 创建擦亮任务，检查服务端与手机。 | J24: 逐operation映射强类型命令并接真实任务页。 | K24: 每类有API、APK recipe与真机证据，不靠toast验收。 | L24: T077 | N24: S15
A25: B020 | B25: P1 | C25: 需求差距 | D25: 未处理 | F25: 闲鱼/扩展任务 | G25: 鱼币、评价、重发等只记录本地配置 | H25: XianyuExtraTaskView.createTask只saveExtraConfig/recordExtraTask。 | I25: 创建每种extra kind并观察无真实任务。 | J25: 15类逐项接通；保留字段语义；不要把一键小刀误写成一键降价。 | K25: 所有kind有schema映射和独立验收，风险操作防重。 | L25: T077 | N25: S16、S17
A26: B021 | B26: P1 | C26: 需求差距 | D26: 未处理 | F26: 小红书/后端 | G26: 后端目标包allowlist不含小红书 | H26: mobile_service._insert_task只允许Companion和闲鱼。 | I26: 尝试创建小红书目标任务，观察拒绝。 | J26: 扩展TargetAppRegistry且任务创建按设备上报版本/能力校验。 | K26: 支持小红书可下发；未知包仍拒绝。 | L26: T009、T012 | M26: 2026-09-06 CommandV1 已声明 com.xingin.xhs； mobile_service._insert_task allowlist 仍无小红书，B021 未完全关闭。 | N26: S04
A27: B022 | B27: P1 | C27: 需求差距 | D27: 代码已修/待联调 | E27: ZCode | F27: 小红书/APK | G27: APK本地allowlist及locator也不含小红书 | H27: CloudCtlAccessibilityService.ensureReady和TargetLocatorRegistry只支持两个包。 | I27: 传小红书目标给本地执行器。 | J27: 注册已签名平台定义与locator集；保留本地授权限制。 | K27: 正确包通过，篡改包或未发布recipe拒绝。 | L27: T009、T020 | M27: 2026-09-07 Companion 生命周期/outbox/checkpoint/防重 journal 已落地；真机证据待联调。 | N27: S28、S29
A28: B023 | B28: P1 | C28: 需求差距 | D28: 未处理 | F28: 平台兼容 | G28: 定位器没有目标App版本维度 | H28: TargetLocatorRegistry按package分支，闲鱼大量固定contentDescription。 | I28: 对两个App版本运行locator探测并比较。 | J28: APK自动上报版本；包内兼容范围+页面指纹；未知页面暂停等待适配，不要求用户手填版本。 | K28: 升级后不盲点；兼容失败回报明确原因和证据。 | L28: T009、T039 | N28: S29、S04
A29: B024 | B29: P1 | C29: 静态确认 | D29: 代码已修/待联调 | E29: ZCode | F29: APK/启动 | G29: 执行前没有统一拉起目标App | H29: runNext直接service.execute；ensureReady要求root.packageName==target。 | I29: 手机停桌面时创建闲鱼发布任务。 | J29: 增加launch→等待目标包→账号探测→页面归一化；已知权限弹窗单独处理。 | K29: 桌面/其它App起点均能开始，未安装报APP_NOT_INSTALLED。 | L29: T021 | M29: 2026-09-07 Companion 生命周期/outbox/checkpoint/防重 journal 已落地；真机证据待联调。 | N29: S25、S28
A30: B025 | B30: P0 | C30: 待复现风险 | D30: 代码已修/待联调 | E30: ZCode | F30: APK/素材 | G30: 下载素材在执行try与续租之前 | H30: runNext素材校验与deliver位于try之前，sendInitialHeartbeat与周期续租在其后。 | I30: 大视频限速下载超过lease；或下载抛异常；观察本地RUNNING和服务端重领。 | J30: 领取后立即续租；下载也受任务状态机与取消控制；异常必须持久化可恢复状态。 | K30: 慢下载不失租；下载失败可重试且不卡死；旧租约不得继续执行UI。 | L30: T016、T047、T021 | M30: 2026-09-07 Companion 生命周期/outbox/checkpoint/防重 journal 已落地；真机证据待联调。 | N30: S25、S26
A31: B026 | B31: P1 | C31: 静态确认 | D31: 代码已修/待联调 | E31: ZCode | F31: APK/诊断 | G31: 外层吞掉具体错误码和取消原因 | H31: runNext catch(Exception)调用finish(false)默认TASK_EXECUTION_FAILED。 | I31: 制造LOCATOR_NOT_FOUND、STEP_TIMEOUT和服务取消。 | J31: 分层处理业务异常/取消/未知异常；保留code、step、safeMessage、correlationId。 | K31: 不同错误分别可见；用户暂停不被标普通失败。 | L31: T014、T021 | M31: 2026-09-07 Companion 生命周期/outbox/checkpoint/防重 journal 已落地；真机证据待联调。 | N31: S25、S27、S26
A32: B027 | B32: P1 | C32: 静态确认 | D32: 代码已修/待联调 | E32: ZCode | F32: APK/事件 | G32: 运行中事件仅入本地outbox，主循环执行后才flush | H32: syncLoop在runNext前flushOutbox；step回调只recordStepEvent。 | I32: 运行长任务并比较手机journal和云端events到达时间。 | J32: 独立outbox上传协程，按task/sequence有序重试，不阻塞执行线程。 | K32: 联网时步骤事件及时到云端；断线补传不乱序。 | L32: T014、T022 | M32: 2026-09-07 Companion 生命周期/outbox/checkpoint/防重 journal 已落地；真机证据待联调。 | N32: S25、S26
A33: B028 | B33: P1 | C33: 需求差距 | D33: 代码已修/待联调 | E33: ZCode | F33: 任务/证据 | G33: 截图证据未进入云端任务附件闭环 | H33: executor Screenshot仅校验path/hash并log；journal payload仅detailCode。 | I33: 执行screenshot步骤后查看服务端任务证据。 | J33: 对象上传+Evidence元数据+事件引用，失败尽力上传最后一帧。 | K33: Web可读原截图，hash/step/task匹配，越权拒绝。 | L33: T050、T022 | M33: 2026-09-07 Companion 生命周期/outbox/checkpoint/防重 journal 已落地；真机证据待联调。 | N33: S27、S25
A34: B029 | B34: P1 | C34: 需求差距 | D34: 代码已修/待联调 | E34: ZCode | F34: APK/恢复 | G34: 后置条件已满足被一律判为失败 | H34: Tap检测postcondition存在抛POSTCONDITION_ALREADY_MET。 | I34: 暂停在点击后、记录前；恢复相同步骤。 | J34: 按动作与检查点做resume guard；核实是本任务已完成后跳过；证据不充分进RECONCILING，不能简单全改成功。 | K34: 既不重复发布/删除，也不把无关页面误认成功。 | L34: T023、T024、T027 | M34: 2026-09-07 Companion 生命周期/outbox/checkpoint/防重 journal 已落地；真机证据待联调。 | N34: S27
A35: B030 | B35: P1 | C35: 需求差距 | D35: 代码已修/待联调 | E35: ZCode | F35: APK/恢复 | G35: 进程重启把运行任务标失败 | H35: AutomationStore.recoverInterruptedRuns写FAILED_RESTART；缺状态变量/循环游标检查点。 | I35: 执行中重启Companion，观察任务终态。 | J35: 持久化checkpoint与commit journal，重启后先恢复到暂停/核对，不重放不可逆动作。 | K35: 同taskId可安全恢复；不确定提交等待核对。 | L35: T023、T027 | M35: 2026-09-07 Companion 生命周期/outbox/checkpoint/防重 journal 已落地；真机证据待联调。 | N35: S26
A36: B031 | B36: P1 | C36: 需求差距 | D36: 代码已修/待联调 | E36: ZCode | F36: 结果协议 | G36: 成功result固定空JSON | H36: AutomationStore.enqueueTerminalLocked成功仅发送result:{}。 | I36: 完成发布/采集后检查complete body。 | J36: 按commandType发送typed result；大数据分批ingest，result带batch统计。 | K36: 非法resultType拒绝；发布/订单/指标各有结构化结果。 | L36: T014、T022 | M36: 2026-09-07 Companion 生命周期/outbox/checkpoint/防重 journal 已落地；真机证据待联调。 | N36: S26、S06
A37: B032 | B37: P1 | C37: 静态确认 | D37: 未处理 | F37: 媒体/权限 | G37: deliveryId没有绑定任务/设备/素材授权 | H37: media_manifest按tenant+assetIds查；deliveryId原样回显；download仅按tenant检查。 | I37: A设备请求分配给B的已知assetId，检查是否获文件。 | J37: MediaDelivery绑定device/task/assetSet/expiry；所有下载入口强制校验并审计。 | K37: 同租户不同设备未授权素材403；取消/过期delivery失效。 | L37: T046 | N37: S04、S05
A38: B033 | B38: P1 | C38: 静态确认 | D38: 代码已修/待联调 | E38: ZCode | F38: 账号/权限 | G38: 手机账号状态接口返回租户全部账号 | H38: account_status先取tenant全部accounts；boundToDevice只是布尔字段。 | I38: A/B各绑不同账号；A调accounts/status。 | J38: 只返回当前设备活跃绑定账号的最小字段，去掉无关账号列表。 | K38: A看不到B独有账号；解绑后立即不可见。 | L38: T010 | N38: S04
A39: B034 | B39: P1 | C39: 需求差距 | D39: 代码已修/待联调 | E39: ZCode | F39: 账号/绑定 | G39: 未保证同设备同平台仅一个当前账号 | H39: bind_account_device只检查account/device配对，不查该设备同平台其它BOUND。 | I39: 同台设备先绑闲鱼甲再绑乙，检查两个是否均BOUND。 | J39: 事务锁设备；平台维度唯一活跃绑定；换绑递增bindingVersion并阻止旧任务自动跟随。 | K39: 闲鱼甲/乙不能同时BOUND；闲鱼+小红书可并存；历史保留甲。 | L39: T010、T011 | M39: 2026-09-06 bind_account_device 事务锁设备；同平台挤掉旧 BOUND； 换绑失败旧 QUEUED 任务 ACCOUNT_CHANGED；ownership 接口保留甲历史。 | N39: S02、S03
A40: B035 | B40: P1 | C40: 待复现风险 | D40: 代码已修/待联调 | E40: ZCode | F40: 设备/身份 | G40: 同设备可存在多个活跃Companion实例 | H40: mobile_binding唯一键device_id+app_instance_id；enroll未撤销其它实例。 | I40: 两个实例用不同enrollment绑定同一device；并发claim。 | J40: 一期每device一个active binding；重绑撤销旧token并抬高控制epoch。 | K40: 旧token无法领任务/远控；唯一活跃实例有DB约束。 | L40: T007 | N40: S04、S03
A41: B036 | B41: P0 | C41: 待复现风险 | D41: 代码已修/待联调 | E41: ZCode | F41: 任务/互斥 | G41: mobile claim缺设备级串行仲裁 | H41: claim锁任务行，未先锁设备/统一DeviceLease；两个并发请求均可能先看到无active。 | I41: Postgres并发2个claim，设备排队2任务，循环测试。 | J41: 先锁设备并取得统一fencing lease；再claim；所有执行路径共用同一仲裁。 | K41: 并发100次仅1个活跃writer；旧epoch后续动作被拒。 | L41: T016 | M41: 2026-09-06 claim 与 DeviceLease 共用 writer；暂停队头不越过；maintenance 拒绝 AUTO。 | N41: S04、S03
...

Sheet 02_实施任务
A1: 02 / 一期实施任务与进度
A2: 按编号与依赖执行；每行8步；所有任务目前均未实施。代码完成→联调→真机→验收，证据齐备再标“已完成”。
A3: 左侧状态/负责人可维护；详细步骤分两列防止挤成一格。共用组件任务也必须完成，不要在每个页面另造本地存储、队列、签名或设备写锁。
A5: 编号 | B5: 阶段 | C5: 任务名称 / 优先级 | D5: 状态 | E5: 负责人 | F5: 前置任务 | G5: 代码位置（新增处已标） | H5: 实施步骤 1–4 | I5: 实施步骤 5–8 | J5: 接口 / 数据契约 | K5: 验收测试（必须执行） | L5: 交付要求 | M5: 关联问题 / 需求 | N5: 提交 / 证据 / 阻塞说明 | O5: 来源编号
A6: T001 | B6: A 基线与身份 | C6: P0｜锁定代码并跑真实基线 | D6: 已完成 | E6: AI Agent | F6: 无 | G6: README.md；AGENTS.md；package.json；pyproject.toml；mobile/companion | H6: 1. 记录git rev-parse HEAD；与本次b394475比较并生成差异清单 2. 读取AGENTS/README，不直接升级依赖；复制环境模板时不用真实密钥入库 3. 按README准备Python3.12+/Node22+/pnpm10.15+/JDK17或21/SDK35 4. 执行pip install -e ".[dev]"与pnpm install --frozen-lockfile | I6: 5. 执行ruff format --check .、ruff check .、pyright、mypy、pytest -q 6. 读取package.json的真实scripts后依次跑lint、typecheck、test、build和e2e；Android在工程目录执行./gradlew test lint assembleDebug；缺脚本记录实际替代命令 7. 无Android SDK/设备或依赖安装失败时写阻塞原因，不填通过 8. 保存docs/phase1/baseline.md，逐命令记录退出码和原始日志 | J6: 基线失败与后续回归分开记录；本次没有实际运行上述工程命令。 | K6: 验收1：干净环境能复跑同一SHA 验收2：失败项逐条入01代码审阅 验收3：不把mock或编译成功写成真机发布成功 | L6: 代码、测试与执行日志；完成后填写commit SHA和证据路径 | M6: 问题：B061、B062、B063 需求：工程交付基线 | O6: S31、S01
A7: T002 | B7: A 基线与身份 | C7: P0｜全仓覆盖和问题补录 | D7: 已完成 | E7: AI Agent | F7: T001 | G7: apps/{web,studio}；services/*；edge/gateway；mobile/{companion,dpc}；packages/*；infra；tests | H7: 1. 按文件夹列出语言、入口、依赖和测试，生成覆盖矩阵 2. 全仓检索localStorage、mock、TODO、pass、NotImplemented、except Exception及硬编码成功 3. 检查API路由→service→DB→outbox→APK的每个真实调用链 4. 复核鉴权、tenant过滤、上传、SQL、密钥日志、反序列化和依赖版本风险 | I7: 5. 针对本表待复现项补Postgres并发及契约回归测试 6. 列出未读目录、未运行测试、无硬件功能，不假设已覆盖 7. 新发现按B新增编号记录位置、触发、修复、验收 8. 一期外问题记录但不自动扩展一期开发范围 | J7: 覆盖率指已审阅文件/已执行测试，不能用“全仓无报错”替代业务验收。 | K7: 验收1：每个一级目录都有审阅状态 验收2：新旧Bug可追溯 验收3：一期外代码变更有明确原因 | L7: 代码、测试与执行日志；完成后填写commit SHA和证据路径 | M7: 问题：B063 需求：工程交付基线 | O7: S31、S01
A8: T003 | B8: A 基线与身份 | C8: P0｜写分层ADR并确定复用边界 | D8: 已完成 | E8: AI Agent | F8: T001 | G8: docs/adr（新增一期ADR）；services/control-api；services/temporal-worker；packages/automation-sdk | H8: 1. 盘点已有租户、账号、设备租约、PublishPlan/Snapshot、commit ledger、自动化包签名和outbox 2. 保留Control API模块化服务，不为百台设备新增无必要微服务 3. 业务任务由云端创建；APK下载已发布Recipe并本地跑状态图，云端不循环下发每一步 4. 复用Temporal负责预约/周期触发；DB为任务事实，Redis只用于可替换信令分发 | I8: 5. 视频走MediaProjection/WebRTC/TURN；指令、媒体文件、实时视频分别传输 6. 写唯一任务与唯一设备写锁约定，防止新旧执行链同时下发 7. 声明Root/Device Owner非一期默认前提，普通系统授权不能绕过 8. ADR列字段/API新增位置与旧路径迁移开关 | J8: 旧PublishPlan/Target/提交账本不得另造并行发布事实；Edge仅开发诊断。 | K8: 验收1：同一设备不存在两套独立写锁 验收2：有新旧功能开关及回滚路线 验收3：所有任务能定位唯一状态来源 | L8: 代码、测试与执行日志；完成后填写commit SHA和证据路径 | M8: 问题：新增实现/联调 需求：R07、R18 | O8: S31、S02、S03
A9: T004 | B9: A 基线与身份 | C9: P1｜逐字段盘点及31项闲鱼目录覆盖 | D9: 待联调 | E9: ZCode | F9: T001 | G9: apps/web/src/data/operations-catalog.ts；views/OperationView.vue或实际动态页面分发入口（全库定位） | H9: 1. 读取31个闲鱼titles并保留原operationId，记录具体渲染页面 2. 按原始一期清单列产品6项、商品3项、帖子、小红书、订单、采集 3. 逐页面提取v-model字段、类型、枚举、默认值和按钮语义 4. 形成field-map.json：UI字段→DTO→快照字段→Recipe消费→验收用例 | I9: 5. 主/副闲鱼切换与新单平台单账号需求冲突时禁用旧多开选项并注明原因 6. 已下线发布/删除帖子不可静默剔除，转可用性验证任务 7. 同名地址池/水印/采集入口映射共享服务，禁止重复建库 8. CI断言每个一期可编辑字段已映射或明确受阻，不能静默忽略 | J9: 字段仅存库不算发布实现；平台不支持的字段须保留数据并给出明确不支持原因。 | K9: 验收1：31项均有处理归属 验收2：没有开启但未消费的字段 验收3：旧blocked不作为永不实现的依据 | L9: 代码、测试与执行日志；完成后填写commit SHA和证据路径 | M9: 问题：B053、B062 需求：R16、R19、R20 | N9: 2026-09-06 field-map.json 已生成；31项闲鱼目录保留原ID；发布/删除帖子 AVAILABILITY_PENDING。Web 101 tests passed。 | O9: S20、S18、S17
A10: T005 | B10: A 基线与身份 | C10: P1｜生产API真相与真实登录态 | D10: 待联调 | E10: ZCode | F10: T001、T003 | G10: apps/web/src/api/product-catalog.ts；api/post-catalog.ts；stores/session.ts；env.d.ts | H10: 1. 新增显式api/mock环境模式并默认生产api 2. 移除404/501隐式切本地；禁止错误后继续副作用请求 3. 统一ApiError(code,message,requestId,fieldErrors) 4. 复用或新增GET /api/v1/me，session从真实身份加载 | I10: 5. can()读权限集合，dev stub仅测试开发构建 6. 业务缓存只在API成功后失效刷新；保留用户未提交表单但不伪造已保存 7. 清点相关localStorage键，迁移工具单独处理 8. 补生产404、401、409、500及刷新恢复测试 | J10: UI权限只改善体验，后端必须独立鉴权；生产API缺失不能自动写本地。 | K10: 验收1：断API保存失败且无业务本地新增 验收2：低权限不能远控/发版 验收3：清空localStorage不丢真实业务数据 | L10: 代码、测试与执行日志；完成后填写commit SHA和证据路径 | M10: 问题：B004、B040 需求：R18 | N10: 2026-09-06 生产 404/501 不再写 localStorage；session 从 /api/v1/session 加载。product-catalog-fail-closed.spec.ts 通过。 | O10: S08、S09、S24
A11: T006 | B11: A 基线与身份 | C11: P1｜统一设备/文件/版本发布权限 | D11: 待联调 | E11: ZCode | F11: T003 | G11: services/control-api/src/cloudctl_api/auth.py；services.py；mobile_routes.py；packages/domain权限定义 | H11: 1. 复用tenant和actor模型，列device.read/control、task.create、recipe.publish、data.delete权限 2. 所有设备、任务、媒体、订单查询必须带tenant并验证资源关系 3. Companion凭据只能访问自身任务与绑定账号，不可用操作者API 4. 新增审计动作：接管、恢复、换绑、发布版本、删除数据 | I11: 5. 网页令牌不放查询URL或公开媒体地址；日志脱敏 6. 写两个tenant和同tenant两设备的越权测试 7. 写入操作保留幂等键和requestId 8. 旧权限兼容映射写迁移说明，不能直接去掉现有鉴权 | J11: 一期单租户运行也必须过跨租户测试；后续二期不需重建所有主键。 | K11: 验收1：跨tenant请求404/403 验收2：设备A不能读B任务/素材 验收3：发版必须操作者身份及权限 | L11: 代码、测试与执行日志；完成后填写commit SHA和证据路径 | M11: 问题：B040 需求：R18 | N11: 2026-09-06 新增 device.control/task.create/recipe.publish/data.delete；test_phase1_permissions.py 通过。 | O11: S02、S04、S05
A12: T007 | B12: A 基线与身份 | C12: P1｜设备注册、重绑与凭据撤销 | D12: 待联调 | E12: ZCode | F12: T006 | G12: services/control-api/src/cloudctl_api/mobile_service.py、db.py；mobile/companion/app/src/main/java/com/company/cloudctl/companion/security/与network/ | H12: 1. 复核现有enrollment一次性码、有效期和token摘要机制并复用 2. 同device注册新instance时锁设备并撤销其它活跃binding 3. 增加唯一活跃binding约束或active_binding_id事实字段 4. 重新绑定递增controlEpoch，旧token和旧会话立即失效 | I12: 5. Companion用安全存储保存凭据，不在日志打印 6. 补在线/失联/未授权状态，不用手机可达IP做身份 7. 暴力尝试注册码限速，错误不泄露账号信息 8. 迁移时重复活跃binding先列冲突报告再处理 | J12: POST /api/v1/mobile/enrollments与/companion/v2/enroll沿用；新字段须向后兼容。 | K12: 验收1：重绑后旧token401 验收2：并发注册只有一个活跃实例 验收3：手机通过SIM能注册和心跳 | L12: 代码、测试与执行日志；完成后填写commit SHA和证据路径 | M12: 问题：B035 需求：R02 | N12: 2026-09-06 重绑撤销旧 Companion token 并递增 controlEpoch；test_reenroll_revokes_previous_companion_instance 通过。迁移 002_device_control_epoch.sql 待生产执行。 | O12: S04、S03、S05
A13: T008 | B13: A 基线与身份 | C13: P1｜自动探测真实设备系统与能力 | D13: 进行中 | E13: ZCode | F13: T007 | G13: mobile/companion/app/src/main/java/com/company/cloudctl/companion/device/LocalHealthCollector；service/CompanionSyncService.kt；services/control-api/src/cloudctl_api/mobile_schemas.py | H13: 1. 上报manufacturer/model、SDK_INT、Android版本、ROM摘要及Companion版本 2. 分别探测无障碍、gesture、截图、MediaProjection状态、输入方式和可用存储 3. 网络只上报WIFI/CELLULAR/UNKNOWN等必要信息，不伪造延迟/信号 4. 后端存lastSeen和capabilitiesVersion，Web显示未知/过期状态 | I13: 5. 用实际Note9采集报告，不通过机型猜Android版本 6. 保持当前minSdk29基线待实测，不擅自抬到30以上 7. 缺权限时给手机本地引导与Web提示，不自动批准系统授权 8. 增加设备能力JSON fixture与前后端契约测试 | J13: heartbeat增加可选字段兼容旧APK；capability不可用需reasonCode。 | K13: 验收1：实际Note9有设备报告 验收2：断开权限后任务前置校验失败 验收3：WiFi/蜂窝切换真实反映 | L13: 代码、测试与执行日志；完成后填写commit SHA和证据路径 | M13: 问题：B048 需求：R06 | N13: 2026-09-06 heartbeat 增加 sdkInt/model/network/mediaProjection。2026-09-06 ADB 真机 OnePlus LE2100 / Android 14 / SDK 34。 Companion com.company.cloudctl.companion 0.1.0 versionCode=1 minSdk=29 targetSdk=35。 闲鱼 com.taobao.idlefish 7.27.90 versionCode=516。 小红书 com.xingin.xhs 8.50.1 versionCode=8501132。 基线机型是红米 Note9，当前连接的是 OnePlus 9R，不能冒充 Note9 验收。 | O13: S30、S25、S06
A14: T009 | B14: A 基线与身份 | C14: P1｜平台包/版本/账号能力自动探测 | D14: 待联调 | E14: ZCode | F14: T008 | G14: mobile/companion/app/src/main/java/com/company/cloudctl/companion/automation/TargetLocatorRegistry.kt；services/control-api/src/cloudctl_api/mobile_service.py、db.py | H14: 1. 通过PackageManager读取闲鱼、小红书实际包名、versionCode/versionName 2. 将包可见性queries写Manifest并在真机核对 3. 服务端复用Device.target_app_versions并存probe时间，不再让用户手填 4. 引入TargetAppRegistry包名、平台、所需权限、兼容Recipe范围 | I14: 5. 无安装/无授权/未知页面分别返回错误，不一律TASK_FAILED 6. 平台UI变更用签名Recipe更新，不保证未测版本自动兼容 7. 创建和真正执行任务时各校验一次，避免排队期间升级漂移 8. 未知版本允许只读探测，禁止不可逆动作盲跑 | J14: 版本只是适配选择与证据，不作为用户必须知道的产品输入。 | K14: 验收1：卸载/升级后正确上报 验收2：官方单开小红书可注册 验收3：未知包本地和后端都拒绝 | L14: 代码、测试与执行日志；完成后填写commit SHA和证据路径 | M14: 问题：B021、B022、B023 需求：R17 | N14: 2026-09-06 真机已安装闲鱼7.27.90、小红书8.50.1、Companion 0.1.0。 CommandV1 允许 com.xingin.xhs；mobile_service._insert_task 仍只允许 Companion/闲鱼，小红书任务下发未接通。2026-09-06 ADB 真机 OnePlus LE2100 / Android 14 / SDK 34。 Companion com.company.cloudctl.companion 0.1.0 versionCode=1 minSdk=29 targetSdk=35。 闲鱼 com.taobao.idlefish 7.27.90 versionCode=516。 小红书 com.xingin.xhs 8.50.1 versionCode=8501132。 基线机型是红米 Note9，当前连接的是 OnePlus 9R，不能冒充 Note9 验收。 | O14: S04、S29、S28
A15: T010 | B15: A 基线与身份 | C15: P1｜每平台唯一账号与换绑事务 | D15: 待联调 | E15: ZCode | F15: T009、T006 | G15: services/control-api/src/cloudctl_api/services.py bind_account_device；mobile_service.py account_status；db.py | H15: 1. 复用PlatformAccount/AccountDeviceBinding；增加platform和bindingVersion或等价约束 2. 事务锁device，确保同device同platform仅一条BOUND；两个平台可并存 3. 绑定需APK本地识别登录账号，无法识别时标未核验，不编造账号ID 4. 换绑先暂停/取消该平台未完任务，再更新绑定；旧绑定记录保留 | I15: 5. 创建任务冻结accountId和bindingVersion；执行前重新比对 6. accounts/status只返回当前设备BOUND账号的必要字段 7. 订单和发布实例按accountId查询而非按当前device归属 8. 添加绑定/解绑/重绑/并发冲突及审计测试 | J15: 不保存平台登录密码；secretRef如旧模型必填，调整为适用授权方式的可选字段。 | K15: 验收1：1闲鱼+1小红书通过 验收2：两个闲鱼账号不能同时BOUND 验收3：换绑后旧排队任务ACCOUNT_CHANGED | L15: 代码、测试与执行日志；完成后填写commit SHA和证据路径 | M15: 问题：B033、B034 需求：R10 | N15: 2026-09-06 同设备同平台仅一条 BOUND；闲鱼+小红书可并存。 换绑递增 bindingVersion，旧排队任务 ACCOUNT_CHANGED。 tests: test_one_bound_account_per_device_platform_and_history_preserved 与 test_rebind_fails_queued_task_with_account_changed 通过。 迁移 003_account_binding_ownership.sql 未应用到生产库。 | O15: S02、S04、S03
A16: T011 | B16: A 基线与身份 | C16: P1｜账号换绑后的数据归属与旧任务阻断 | D16: 待联调 | E16: ZCode | F16: T010 | G16: 发布/订单/统计模型；账号页面；任务创建服务 | H16: 1. 内容库Product/Post作为租户资产，不强制绑定某个账号 2. 已发布Listing、订单、指标及任务快照绑定原accountId 3. 保存deviceIdAtExecution与bindingVersion用于追溯 4. 换绑不批量UPDATE历史accountId，不根据当前设备动态归属 | I16: 5. 账号归档不级联删除订单/证据；删除走统一用户删除流程 6. 周期任务固定账号；换绑后暂停该计划，不能自动跟随新账号 7. Web支持按历史账号查数据并标已解绑 8. 写甲→乙换绑后查询和周期触发用例 | J16: 账号历史保留不等于永不允许删除；用户删除有独立权限与引用策略。 | K16: 验收1：甲订单依然属于甲 验收2：乙无法误执行甲任务 验收3：历史设备与当前绑定都可解释 | L16: 代码、测试与执行日志；完成后填写commit SHA和证据路径 | M16: 问题：B034 需求：R10、R13 | N16: 2026-09-06 Product/Post 仍是租户资产。任务/发布目标冻结 accountId、bindingVersion、deviceIdAtExecution。 GET /api/v1/accounts/{id}/ownership 可查已解绑账号历史。换绑不改写历史 accountId。 周期计划完整模型仍待 T017；当前对 DRAFT/SCHEDULED/QUEUED 发布计划暂停为 CANCELED。 | O16: S02、S03
A17: T012 | B17: B 任务与执行 | C17: P0｜高层指令与强类型参数契约 | D17: 待联调 | E17: ZCode | F17: T003、T009、T004 | G17: contracts/phase1（新增）；packages/api-contracts；services/control-api/src/cloudctl_api/mobile_schemas.py；APK parser | H17: 1. 定义CommandV1：taskId、attemptId、commandType、deviceId、accountId、bindingVersion 2. 加入snapshot{id,sha256}、recipe{versionId,sha256,engineMinVersion}、targetPackage、requiredCapabilities 3. 加入lease{controlEpoch,expiresAt}及mediaDeliveryId，不传长期下载密钥；本地用单调时钟维护租约截止 4. 按commandType做discriminated union参数schema，未知字段和动作拒绝 | I17: 5. 保留旧steps读取兼容开关，新业务不再云端生成低层点击循环 6. 生成TS/Python/Kotlin同一组合法和非法fixture 7. 定义协议协商与UNSUPPORTED_PROTOCOL/RECIPE错误 8. 任何v1变更先更新schema和fixtures再改实现 | J17: 手机只消费冻结参数和已发布本地Recipe；动态任意shell/DEX/JS执行均不在协议中。 | K17: 验收1：三端解析同fixture一致 验收2：错设备/错账号/错schema拒绝 验收3：云端命令不含未授权执行代码 | L17: 代码、测试与执行日志；完成后填写commit SHA和证据路径 | M17: 问题：B021 需求：R07 | N17: 2026-09-06 CommandV1 schema contracts/phase1/command-v1.schema.json；Python/TS/Kotlin 同 fixture。 拒绝 shell/DEX/JS/未知字段。test_command_v1.py 通过。 Companion claim 路径仍发 cloudctl.mobile/v1 steps，尚未用 CommandV1 替换生产下发。 | O17: S06、S29、S27
A18: T013 | B18: B 任务与执行 | C18: P0｜统一业务任务API与唯一状态源 | D18: 进行中 | E18: ZCode | F18: T012、T010 | G18: services/control-api/src/cloudctl_api/db.py、services.py、mobile_service.py；新增platform_tasks.py/routes | H18: 1. 新增PlatformTask映射现有MobileTask尝试；发布任务引用现有PublishPlan/Target而非复制发布账本 2. 统一TaskState：QUEUED/WAITING_MATERIALS/PREFLIGHT/RUNNING/PAUSE_REQUESTED/PAUSED_WAITING_USER/RESUME_CHECK/RECONCILING/CANCEL_REQUESTED及终态；AUTO/REMOTE是独立控制模式 3. 创建任务事务冻结账号、指令、参数，idempotencyKey同内容返回原任务 4. 同key不同内容409；批量设备创建独立taskId，可共享batchId筛选 | I18: 5. 新增list/detail/cancel/retry API与游标分页，不固定只取200条；retry仅可判定安全失败，不确定提交先核对 6. 只有状态机服务能写状态；Web与APK不可随意PATCH成功 7. 完成/失败/取消重复回调应幂等，不可覆盖既有不同终态 8. 保留createdBy、attempt、scheduledFor和停滞原因用于排障 | J18: 新增/api/v1/platform-tasks；原/api/v1/mobile/tasks为底层兼容，不另建业务队列。 终态限定SUCCEEDED/FAILED/CANCELLED/EXPIRED；REMOTE不是业务任务终态。 | K18: 验收1：双击只建1任务 验收2：201条历史可分页查全 验收3：跨设备并行、同设备仅顺序执行 | L18: 代码、测试与执行日志；完成后填写commit SHA和证据路径 | M18: 问题：B059 需求：R09 | N18: 2026-09-06 新增 /api/v1/platform-tasks，映射 MobileTask，不另建队列。幂等双击返回原任务；deviceIds 生成独立 taskId 共享 batchId；游标分页。取消 QUEUED→CANCELLED；ACCOUNT_CHANGED 不可 retry。test_platform_tasks.py 通过。迁移 004 未上生产库。 | O18: S04、S03、S02
A19: T014 | B19: B 任务与执行 | C19: P1｜步骤事件、错误和结构化结果 | D19: 进行中 | E19: ZCode | F19: T013 | G19: contracts/phase1/events/results；services/control-api/src/cloudctl_api/mobile_schemas.py、mobile_service.py | H19: 1. 事件含taskId、attemptId、sequence、stateId/stepId、eventType、occurredAt、receivedAt 2. 错误含code、safeMessage、locatorRef、appVersion、recipeVersion和evidenceRefs 3. 每个command定义resultType/schemaVersion；发布、批量操作、订单、采集各不同 4. 大列表不塞complete，使用batch ingest结果引用 | I19: 5. 重复sequence+同payload返回成功，异payload冲突；处理缺口补传 6. 加入pause/resume/reconcile相关事件，不用FAILED代替暂停 7. 接口限制body大小且敏感字段不进普通日志 8. Web事件流使用现有events/outbox模式加游标重连 | J19: UTC保存时间；业务时区仅调度解释；不信任设备时钟作为授权有效期唯一依据。 | K19: 验收1：不同失败code保持原义 验收2：事件重放不乱序 验收3：错误resultType被422拒绝 | L19: 代码、测试与执行日志；完成后填写commit SHA和证据路径 | M19: 问题：B026、B027、B031 需求：R05 | N19: 2026-09-06 事件增加 attemptId/stepId/receivedAt；PAUSE_* 不记 FAILED；错误 resultType 422。契约 contracts/phase1/events/task-event.schema.json。现有事件重放/缺口 409 仍有效。 | O19: S04、S06、S26
A20: T015 | B20: B 任务与执行 | C20: P1｜不可变业务快照和资源解析规则 | D20: 待联调 | E20: ZCode | F20: T013 | G20: 复用PublishSnapshotRow；新增通用TaskSnapshot或等价结构；services/control-api/src/cloudctl_api/services.py | H20: 1. 发布快照包含最终文案、金额、选中池条目、媒体版本/顺序、水印产物与账号绑定版本 2. 随机选取只在云端创建时做一次并记录种子/结果，APK不再次随机 3. 已创建任务只读快照，不读取被编辑后的Product/Post最新值 4. 普通重试复用快照；使用最新内容必须显式创建新任务 | I20: 5. 定时计划保存版本化模板；每个触发生成独立快照且记录模板版本 6. 快照canonical hash服务端计算，手机校验签名/哈希 7. 被删除资源按软删/引用策略保留可执行版本；真正缺失暂停报错 8. 为编辑商品/池/水印之后旧任务不变写集成测试 | J20: 默认地址选择：设备池优先、通用池回退；用户可配置。默认规则是设计值，不伪称用户已指定。 | K20: 验收1：旧任务文案和媒体hash不漂移 验收2：相同任务重试不重新随机 验收3：快照可以独立复现要执行的内容 | L20: 代码、测试与执行日志；完成后填写commit SHA和证据路径 | M20: 问题：新增实现/联调 需求：R07、R19 | N20: 2026-09-06 PlatformTask 创建时冻结 commandPayload 并计算 snapshotSha256；retry 复用原 parameters，不读后续编辑。完整 PublishSnapshot 池/水印解析仍待发布链路接通。 | O20: S02、S03
... A29: T024 | B29: B 任务与执行 | C29: P0｜发布/消耗/删除提交门禁 | D29: 待联调 | E29: ZCode | F29: T023、T016 | G29: 复用发布commit ledger；APK新增ActionJournal；服务端操作结果账 | H29: 1. 对publish/delete/review/推广消耗等定义稳定actionKey=task+目标+动作版本 2. 最终按钮前持久化INTENT及目标参数hash，验证lease和账号 3. 同actionKey存在APPLIED时只核验，不再次点击 4. INTENT后未确认结果记UNKNOWN，不直接按失败重试 | I29: 5. 本地与云端分别保存提交证据和状态，断网时不能依靠云端“保证一次” 6. 真正确认成功才APPLIED；平台ID不可得时返回证据及待核对状态 7. 批量每item独立journal，部分成功任务可继续剩余项 8. 模拟点击后丢ACK/进程退出/换绑，测试无自动二次提交 | J29: 不宣称第三方UI严格exactly-once；采用可判定防重+不确定结果核对。 | K29: 验收1：点击发布后断网不自动再发 验收2：预算/参数变化必须重新确认 验收3：已有成功item不重复处理 | L29: 代码、测试与执行日志；完成后填写commit SHA和证据路径 | M29: 问题：B029、B054 需求：R05、R16 | N29: 2026-09-07 action_journal INTENT/APPLIED/UNKNOWN；同 actionKey APPLIED 不再二次点击。单元测试覆盖。真机断网二次提交仍待联调。 | O29: S31、S04、S26
A30: T025 | B30: B 任务与执行 | C30: P1｜不确定外部结果核对 | D30: 待联调 | F30: T024 | G30: 新增ReconciliationService；平台Recipe核对分支；Web任务详情 | H30: 1. UNKNOWN进入RECONCILING并暂停普通重试 2. 按account、目标itemId、时间、快照摘要及平台可见结果核对 3. 查到唯一结果写APPLIED并恢复后续；明确未提交才允许重新操作 4. 结果相似但不能唯一确认时等待人工，不靠标题相同认定 | I30: 5. 人工确认必须选择已成功/未成功/继续等待并填写证据 6. 记录核对操作者和时间，保留原attempt history 7. 订单/采集重复上传只做幂等upsert，不按发布核对逻辑重跑UI 8. 增加“发布已成功但complete丢失”的E2E用例 | J30: 确认未成功不是无证据强制重试；平台没有可靠身份时保留不确定状态。 | K30: 验收1：未知状态不会自动变成功 验收2：有结果可收敛 验收3：所有人工核对可审计 | L30: 代码、测试与执行日志；完成后填写commit SHA和证据路径 | M30: 问题：B054 需求：R05 | O30: S31、S26
A31: T026 | B31: B 任务与执行 | C31: P0｜暂停请求与安全停止握手 | D31: 已完成 | E31: ZCode | F31: T023、T016 | G31: PlatformTask状态机；APK RecipeContext cancel/pause token；控制API | H31: 1. 新增POST task:pause，状态RUNNING→PAUSE_REQUESTED 2. APK收到控制消息后在安全点停止新动作、取消等待，保存checkpoint 3. 最后gesture完成/取消后回ACK，状态PAUSED_WAITING_USER 4. 后台只有收到安全停止ACK才转移writer给REMOTE | I31: 5. 超时只能等待租约失效后确认停止，不能让两端同时写 6. 已过commit intent进入RECONCILING，仍可看屏但恢复按核对规则 7. 取消单独走CANCEL_REQUESTED/CANCELLED，取消后不提供继续原任务 8. 暂停阻塞本设备FIFO，防止下一任务把现场覆盖 | J31: 控制消息可独立于长任务主循环接收；只读观看不触发pause。 | K31: 验收1：自动任务运行时看屏不暂停 验收2：接管前自动化确已停 验收3：暂停后后续队列不越过 | L31: 代码、测试与执行日志；完成后填写commit SHA和证据路径 | M31: 问题：新增实现/联调 需求：R04、R05 | N31: 真机联调通过 2026-09-07 任务: 54548b87-1963-40ad-a188-3f991e78f04b 状态: PAUSED_WAITING_USER, pauseAckAt=2026-09-07T15:20:52.082937Z, controlMode=REMOTE 后续任务被挡: 850060b6-649a-4573-aa6a-9cd3b9d82647 停在QUEUED 代码: CompanionSyncService心跳前移到预检; AndroidManifest补queries; launchTargetApp兜底 APK: 已编译签名安装 /tmp/cloudctl-app-debug-signed.apk 设备: OnePlus9R b0644fb5, 闲鱼未点发布 | O31: S04、S27、S26
A32: T027 | B32: B 任务与执行 | C32: P0｜交还控制权并继续原任务 | D32: 进行中 | E32: ZCode | F32: T026、T025、T011 | G32: POST task:resume；APK ResumeValidator；任务详情按钮 | H32: 1. REMOTE结束先停止接收旧epoch控制消息并释放远控lease 2. 复核原task仍暂停、account/binding/snapshot/recipe版本一致 3. APK读取当前页面，执行resumeGuard；只有确定安全才从检查点继续 4. 人工已完成当前动作则核验postcondition并推进；未知则停在待人工 | I32: 5. 新的AUTO lease拥有新epoch，旧远控动作即使迟到也拒绝 6. 仍用原taskId，增加resumeCount与审计记录，不从步骤1重跑 7. 账号换了、资产删了或Recipe不兼容时明确阻止继续 8. 写“编辑页中断→人工回到正确页→原任务继续发布”真机用例 | J32: 可以自动回到安全锚点，但不能为恢复随意丢弃人工内容或重复提交。 | K32: 验收1：处理后继续同taskId 验收2：旧远控命令不落地 验收3：无法判定不盲目恢复 | L32: 代码、测试与执行日志；完成后填写commit SHA和证据路径 | M32: 问题：B029、B030 需求：R05 | N32: 2026-09-07 接 T026：同 taskId 从检查点继续；心跳下发 RESUME；新 AUTO epoch；pageVerified=false 拒绝；不从步骤1重跑。真机恢复尚未验收。 | O32: S26、S27
A33: T028 | B33: B 任务与执行 | C33: P1｜统一任务队列、详情与恢复入口 | D33: 进行中 | F33: T013、T014、T026、T027、T018 | G33: apps/web/src/views/TaskQueue/TaskDetail（按现有路由复用）；新增共用任务组件 | H33: 1. 列表从后端分页，支持设备/平台/账号/状态/时间过滤 2. 显示独立taskId、等待原因、当前步骤、版本和队列位置 3. 详情呈现快照、steps、typed result、错误与证据 4. 暂停/接管/继续/取消/核对结果各自独立按钮和权限 | I33: 5. 网络断线显示状态过期，不继续显示伪实时进度 6. 周期计划和已经生成的任务区分，不混作同一状态 7. 事件流断线按cursor补拉，防止漏终态 8. 页面刷新和清localStorage后可恢复所有任务记录 | J33: 长期任务历史可查；无父任务状态；batchId仅过滤。 | K33: 验收1：所有任务页复用同状态组件 验收2：暂停与失败视觉区分 验收3：刷新不丢历史 | L33: 代码、测试与执行日志；完成后填写commit SHA和证据路径 | M33: 问题：B059 需求：R05、R09 | O33: S04、S20
A34: T029 | B34: C 视频与远控 | C34: P0｜设备主动联网的WebRTC会话服务 | D34: 未开始 | F34: T006、T007 | G34: control-api新增RealtimeSessionService；复用edge-hub连接职责；部署TURN | H34: 1. 创建rtc_session表：tenant/device/viewer、状态、过期时间和sessionEpoch，不存视频帧 2. 实现鉴权WSS信令：offer/answer/ICE/close；手机主动建立出站连接 3. 浏览器请求会话必须有device:view权限；控制权另行申请，不因看视频获得控制 4. 接入TURN短期凭据，配置UDP以及TCP/TLS中继路径；凭据不写前端源码 | I34: 5. 信令按sessionId+epoch路由，禁止A设备消息进入B会话 6. 设置心跳、断线重连、会话回收；多实例通过共享会话目录定位设备 7. 部署文档写明公网证书、端口、防火墙、TURN公网地址和出口带宽 8. 在两端不在同一LAN的环境测试直连和强制relay，不把内网成功当蜂窝验收 | J34: POST /devices/{id}/rtc-sessions；WSS signaling；TURN REST短期凭据。接口名称为建议，优先复用现有路由规范。 | K34: 验收1：SIM网络可建立relay视频 验收2：跨租户信令403 验收3：TURN凭据过期不可继续新建会话 | L34: 代码、测试与执行日志；完成后填写commit SHA和证据路径 | M34: 问题：B038 需求：R02、R03 | O34: S35、S36、S31
A35: T030 | B35: C 视频与远控 | C35: P0｜MediaProjection实时采集与前台服务 | D35: 未开始 | F35: T008、T029 | G35: mobile/companion/app/src/main/java/com/company/cloudctl/companion/新增screen/ScreenCaptureService.kt；AndroidManifest.xml；授权Activity | H35: 1. 按设备SDK实现MediaProjection授权入口，明确用户可见授权状态 2. target35声明正确前台服务类型/权限并显示持续通知；按官方启动顺序实现 3. 用户授权后建立一次capture session，持有VirtualDisplay和编码输入Surface 4. 用WebRTC视频源传帧，不JPEG/base64写数据库；默认720p约20fps仅为可调设计值 | I35: 5. 处理屏幕旋转与尺寸变化，发viewportVersion/width/height/rotation 6. 会话存活时浏览器重连复用现有采集，不重复消费授权token 7. 用户撤销/进程死亡后停止并上报NEEDS_CAPTURE_CONSENT；不得承诺静默恢复授权 8. 记录Redmi Note9实际SDK/ROM；测试授权、拒绝、停止、旋转、重连 | J35: CaptureState=IDLE/NEEDS_CONSENT/ACTIVE/STOPPED/ERROR；真实能力上报。 | K35: 验收1：有授权可连续视频 验收2：拒绝授权不崩溃不假在线 验收3：进程死亡后重新授权路径明确 | L35: 代码、测试与执行日志；完成后填写commit SHA和证据路径 | M35: 问题：B038、B048、B049 需求：R03、R06 | O35: S32、S37、S30
A36: T031 | B36: C 视频与远控 | C36: P1｜WebRTC连接、编码和弱网自适应 | D36: 未开始 | F36: T030、T029 | G36: mobile/companion/app/src/main/java/com/company/cloudctl/companion/新增realtime/PeerSessionManager.kt | H36: 1. 集成锁定版本WebRTC库并记录许可证与ABI体积；禁止不固定版本下载 2. 按sessionEpoch创建PeerConnection，验证服务端签发的会话许可 3. 绑定MediaProjection视频轨，协商可用硬件编码，失败提供明确降级原因 4. 配置可调整分辨率、fps、码率上下限，流畅优先但不无上限耗流量 | I36: 5. 上报连接类型、RTT、丢包、发送fps/码率和采集时间，不伪造数字 6. ICE失败做有限重启与relay回退，暂停状态有明确UI 7. 无观看者按生命周期释放/停止发送，不能百台一直高码率推流 8. 测试移动网络切换、信令断连、TURN临时不可用与编码器失败 | J36: RealtimeStatsV1；视频媒体走WebRTC，任务与素材仍走既有HTTPS通道。 | K36: 验收1：强制relay可用 验收2：网络恢复不重启自动任务 验收3：无viewer时无持续高码率上传 | L36: 代码、测试与执行日志；完成后填写commit SHA和证据路径 | M36: 问题：新增实现/联调 需求：R01、R02、R03 | O36: S36、S35、S32
A37: T032 | B37: C 视频与远控 | C37: P0｜可复用实时播放器与设备切换隔离 | D37: 未开始 | F37: T031 | G37: apps/web/src/views/DeviceDetailView.vue；新增components/DeviceLiveScreen.vue | H37: 1. 用video轨替换一期主投屏img轮询，旧截图只作为故障诊断而非验收替代 2. 组件固定持有deviceId/sessionId/epoch；路由切换先关旧会话并清video.srcObject 3. 异步响应校验epoch，A设备迟到帧/回调不能显示或关闭B会话 4. 显示真实连接状态、最后帧时间、网络质量；卡住显示stale | I37: 5. 自动重连只恢复观看，不自动恢复写控制权 6. 处理竖横屏和object-fit留白，输出当前内容区域与viewportVersion 7. 页面销毁/切隐藏页遵循会话保活策略，释放track/listener 8. 模拟快速切设备与延迟answer，验证无串屏 | J37: DeviceLiveScreen提供只读默认模式；控制通过独立租约能力传入。 | K37: 验收1：连续切A/B不串屏 验收2：断网显示卡顿而不是假实时 验收3：主界面真实视频 | L37: 代码、测试与执行日志；完成后填写commit SHA和证据路径 | M37: 问题：B038、B039 需求：R03、R04 | O37: S21、S36
A38: T033 | B38: C 视频与远控 | C38: P1｜长时间观看、重连和授权状态闭环 | D38: 未开始 | F38: T032、T030 | G38: RealtimeSessionService；APK CaptureService；Web设备状态组件 | H38: 1. 明确capture session与browser viewing session是两种生命周期 2. 短时浏览器断线保留已授权采集服务一段可配置grace；无viewer停止发送 3. capture仍存活时重建peer，避免误要求重复授权 4. capture已死亡/被系统回收时上报需现场授权，不绕过系统权限 | I38: 5. 同时观看同设备允许只读；只有一个写控制租约 6. 会话过期只关视频连接，不取消自动化任务 7. 长期观看统计内存/编码资源；每次stop释放surface/track/peer 8. 长任务连续观看30分钟，断开浏览器再连及手机撤销授权各留证据 | J38: 会话TTL/grace为配置；长期云端素材保留不代表永久维持录屏服务。 | K38: 验收1：30分钟观看不因120秒预览过期中断 验收2：重连不多建capture 验收3：授权丢失明确可见 | L38: 代码、测试与执行日志；完成后填写commit SHA和证据路径 | M38: 问题：B049 需求：R03、R04 | O38: S32、S21
A39: T034 | B39: C 视频与远控 | C39: P0｜独立写控制权和时效命令协议 | D39: 未开始 | F39: T026、T029、T016 | G39: 新增RemoteControlSession；contracts/RemoteCommandV1；control lease服务 | H39: 1. 申请REMOTE写权先调用安全暂停，收到ACK后签发新的controlEpoch 2. DataChannel用可靠有序通道发送操作，但每个命令仍校验seq/ttl/epoch 3. 定义tap/swipe/longPress/text/back/home/recents；坐标0..1且附viewportVersion 4. 服务端/设备双侧记录当前有效writer，撤销时立即失效旧epoch | I39: 5. 网络恢复不重放旧点击；过期操作ACK=EXPIRED 6. 只读viewer没有控制token；远控需用户显式点击开始 7. 控制权丢失自动停止发送，自动任务仍按暂停状态等待，不悄悄续跑 8. 写contract测试：重复seq、过期、越权、旧epoch、旋转旧viewport全部拒绝 | J39: RemoteCommand{sessionId,controlEpoch,seq,ttlMs,viewportVersion,action,args}；RemoteAck{seq,status,executedAt}。 | K39: 验收1：看屏不占writer 验收2：旧epoch命令无法落地 验收3：点击后断网不在重连时补点击 | L39: 代码、测试与执行日志；完成后填写commit SHA和证据路径 | M39: 问题：B047 需求：R04、R05 | O39: S36、S04
A40: T035 | B40: C 视频与远控 | C40: P0｜手势和系统键能力 | D40: 未开始 | F40: T034、T020 | G40: mobile/companion/app/src/main/java/com/company/cloudctl/companion/automation/CloudCtlAccessibilityService.kt；新增RemoteCommandExecutor.kt | H40: 1. 入口先验控制token、epoch、seq、ttl和viewport，再执行任何手势 2. 坐标转换基于当前显示区域/旋转/边界，拒绝越界 3. 实现dispatchGesture点按、滑动、长按，记录完成/取消回调 4. 实现系统Back/Home/Recents；权限不足返回明确错误 | I40: 5. 人工远控允许用户操作其它App，不复用闲鱼专属automation allowlist误拦截 6. 自动化执行仍严格限定recipe允许平台；两条权限边界不可混淆 7. 每次旋转抬高viewportVersion，旧坐标命令丢弃 8. 在Note9真机竖横屏、导航栏、键盘出现场景执行九宫格点击测试 | J40: 通用远控原语受REMOTE许可；自动化原语受command/platform许可。 | K40: 验收1：可Home并操作其它App 验收2：竖横屏映射正确 验收3：AUTO未暂停无法远控 | L40: 代码、测试与执行日志；完成后填写commit SHA和证据路径 | M40: 问题：B047 需求：R04、R12 | O40: S28、S36
A41: T036 | B41: C 视频与远控 | C41: P0｜屏幕操作面板与交还自动化 | D41: 未开始 | F41: T035、T032、T027 | G41: apps/web/src/components/DeviceLiveScreen.vue；新增RemoteControlPanel.vue | H41: 1. 获取REMOTE前默认禁用所有写操作，保留观看 2. 按video实际内容矩形而非容器尺寸归一化鼠标坐标，消除letterbox偏差 3. pointer down/move/up区分tap、swipe和长按，限制发送频率 4. 提供Back/Home/Recents、文本输入、结束接管按钮 | I41: 5. 显示命令ACK/超时；不能用按钮动画冒充手机已执行 6. 旋转、stale画面或无控制权时停止坐标发送 7. 人工处理后“交还并继续”调用resume，不新建task 8. 关闭页面释放REMOTE，原任务保持待恢复，不在无人确认下自动继续 | J41: 独立按钮：仅观看／暂停并接管／交还并继续原任务／取消任务。 | K41: 验收1：浏览器缩放不误点 验收2：接管后原taskId可恢复 验收3：关页不偷偷续跑 | L41: 代码、测试与执行日志；完成后填写commit SHA和证据路径 | M41: 问题：B047 需求：R04、R05、R12 | O41: S21
A42: T037 | B42: C 视频与远控 | C42: P1｜明确能力边界的输入与复制粘贴 | D42: 未开始 | F42: T035、T036 | G42: mobile/companion/app/src/main/java/com/company/cloudctl/companion/input/；Web RemoteControlPanel | H42: 1. 优先Accessibility ACTION_SET_TEXT对可编辑节点写入，支持中文和换行 2. 需要复杂键盘时设计用户启用的Companion IME，不能静默切换输入法 3. 电脑粘贴先以显式text命令发送，不依赖后台读系统剪贴板 4. 手机到电脑复制仅在Android允许读取的前台/默认IME上下文执行 | I42: 5. 无法读取剪贴板返回CAPABILITY_UNAVAILABLE，并提供显式分享/输入框通道 6. 不后台持续监听密码/验证码，不把全部剪贴板写日志 7. 文本输入绑定目标焦点与当前viewport，失焦拒绝或提示重新选择 8. 测试中文、emoji、长文本、密码字段拒绝和Android剪贴板限制 | J42: ClipboardBridge是显式用户动作；不承诺所有App的双向实时剪贴板。 | K42: 验收1：中文文本可写 验收2：受限复制清楚提示 验收3：日志不泄露剪贴板内容 | L42: 代码、测试与执行日志；完成后填写commit SHA和证据路径 | M42: 问题：B050 需求：R12 | O42: S33、S28
A43: T038 | B43: C 视频与远控 | C43: P1｜设备卡片、能力和任务观察接入 | D43: 未开始 | F43: T028、T032、T036、T008 | G43: apps/web/src/设备列表视图与DeviceDetailView.vue；device API | H43: 1. 设备列表显示真实online/lastSeen/network/targetApps/当前账号/当前任务 2. 移除固定Wi-Fi延迟和信号强度文案；不可获得显示未知 3. 每张卡只按用户打开才启动视频，不一次打开全部手机视频 4. 任务详情复用同一播放器和步骤时间轴 | I43: 5. 将权限缺失、版本待适配、需要录屏授权分别显示 6. 账号解绑/换绑跳转真实绑定接口并显示历史归属说明 7. 加入排队数量、暂停等待人工原因；不伪造空闲状态 8. 清localStorage、断API、断手机分别测试真实空态和错误态 | J43: GET device detail返回capabilities、accounts、activeTask、networkTelemetry和captureState。 | K43: 验收1：任务中能实时看屏 验收2：SIM网络显示真实类型 验收3：缺权限可定位 | L43: 代码、测试与执行日志；完成后填写commit SHA和证据路径 | M43: 问题：新增实现/联调 需求：R01、R03、R04 | O43: S21、S24
A44: T039 | B44: D 版本与发布 | C44: P1｜自动探测版本的定位器采样与回归 | D44: 未开始 | F44: T009、T020、T023 | G44: mobile/companion/app/src/main/java/com/company/cloudctl/companion/automation/TargetLocatorRegistry.kt；新增测试采样工具；版本包fixtures/ | H44: 1. 读取实际已安装闲鱼/小红书版本，不要求用户提供 2. 建立pageState语义名，locator优先resourceId/层级/类型，多策略文本作后备 3. 为每个关键页面保存脱敏树、截图、应用版本和屏幕状态fixture 4. 实现locator probe runner，列出匹配数与歧义，不允许多匹配默认点第一个 | I44: 5. 未知页面暂停；仅经审核的已知弹窗有处理分支 6. 输入框、最终发布、支付/消耗/删除按钮必须有明确postcondition 7. 版本包声明支持范围与页面指纹，不能一个中文描述适配所有未来版本 8. 生成真机认证记录，未实测版本只标待验证 | J44: LocatorSet{platform,appVersionRange,pageStates,selectors,postconditions}；脚本新版本须回归fixture。 | K44: 验收1：多匹配拒绝盲点 验收2：App升级后安全暂停 验收3：真机采样可重复运行 | L44: 代码、测试与执行日志；完成后填写commit SHA和证据路径 | M44: 问题：B023 需求：R07、R11 | O44: S29、S28
... A125: T120 | B125: J 联调与验收 | C125: P0｜一期端到端完成门槛与交接 | D125: 未开始 | F125: T114、T115、T116、T117、T118、T119、T065、T066、T113 | G125: docs/phase1/acceptance.md；本Excel进度/证据列；release manifest | H125: 1. 按需求R01至R20和31项闲鱼覆盖表逐条列验收用例与对应TaskID 2. 真实10台SIM设备：观看不中断、远控暂停、人工后同task恢复 3. 普通宝贝六类编辑后刷新可读；导入/分组/批量操作数据库一致 4. 小红书图文/视频、闲鱼发布及各授权任务有真实执行结果；不可用平台入口明确阻塞不假通过 | I125: 5. 订单默认全部/指定N及字段可用性、指标历史两次采集都核对 6. 手动发布Recipe和APK升级权限边界通过；账号换绑保留历史 7. P0问题关闭、一期阻塞P1关闭；未测风险保留，不以编码完成等于验收完成 8. 交付commit、迁移、锁定依赖、自动化测试、真机task/证据索引、部署与回滚；更新本表状态 | J125: 完成定义：代码+测试+真实调用+真机证据。平台不可用项须真实证据并保持阻塞，不能由智能体自行豁免。 | K125: 验收1：每项需求有证据 验收2：无静默localStorage假成功 验收3：不把未验证写完成 | L125: 代码、测试与执行日志；完成后填写commit SHA和证据路径 | M125: 问题：B063 需求：R01、R02、R03、R04、R05、R06、R07、R08、R09、R10、R11、R12、R13、R14、R15、R16、R17、R18、R19、R20 | O125: S01、S31
